Workbook

Sheet Auswertung Gesamt
A1: Name | B1: Summe
A2: Lanci | B2: =SUMIF('Auswertung Stage'!$A$2:$A$5,A2,'Auswertung Stage'!B2:V2) -> 43
A3: Sebbo | B3: =SUMIF('Auswertung Stage'!$A$2:$A$5,A3,'Auswertung Stage'!B3:V3) -> 32
A4: Janik | B4: =SUM('Auswertung Stage'!B4:V4) -> 130
A5: Reto | B5: =SUM('Auswertung Stage'!B5:V5) -> 216

Sheet Auswertung Stage
B1: S 01 | C1: S 02 | D1: S 03 | E1: S 04 | F1: S 05
A2: Lanci | B2: =SUMIF(Spieler_Teams!$A:$A,$A2,Spieler_Teams!C:C) -> 43 | C2: =SUMIF(Spieler_Teams!$A:$A,$A2,Spieler_Teams!D:D) -> 15 | D2: =SUMIF(Spieler_Teams!$A:$A,$A2,Spieler_Teams!E:E) -> 10 | E2: =SUMIF(Spieler_Teams!$A:$A,$A2,Spieler_Teams!F:F) -> 38 | F2: =SUMIF(Spieler_Teams!$A:$A,$A2,Spieler_Teams!G:G) -> 40
A3: Sebbo | B3: =SUMIF(Spieler_Teams!$A:$A,$A3,Spieler_Teams!C:C) -> 23 | C3: =SUMIF(Spieler_Teams!$A:$A,$A3,Spieler_Teams!D:D) -> 13 | D3: =SUMIF(Spieler_Teams!$A:$A,$A3,Spieler_Teams!E:E) -> 24 | E3: =SUMIF(Spieler_Teams!$A:$A,$A3,Spieler_Teams!F:F) -> 22 | F3: =SUMIF(Spieler_Teams!$A:$A,$A3,Spieler_Teams!G:G) -> 49
A4: Janik | B4: =SUMIF(Spieler_Teams!$A:$A,$A4,Spieler_Teams!C:C) -> 32 | C4: =SUMIF(Spieler_Teams!$A:$A,$A4,Spieler_Teams!D:D) -> 20 | D4: =SUMIF(Spieler_Teams!$A:$A,$A4,Spieler_Teams!E:E) -> 20 | E4: =SUMIF(Spieler_Teams!$A:$A,$A4,Spieler_Teams!F:F) -> 18 | F4: =SUMIF(Spieler_Teams!$A:$A,$A4,Spieler_Teams!G:G) -> 40
A5: Reto | B5: =SUMIF(Spieler_Teams!$A:$A,$A5,Spieler_Teams!C:C) -> 85 | C5: =SUMIF(Spieler_Teams!$A:$A,$A5,Spieler_Teams!D:D) -> 32 | D5: =SUMIF(Spieler_Teams!$A:$A,$A5,Spieler_Teams!E:E) -> 24 | E5: =SUMIF(Spieler_Teams!$A:$A,$A5,Spieler_Teams!F:F) -> 43 | F5: =SUMIF(Spieler_Teams!$A:$A,$A5,Spieler_Teams!G:G) -> 32

Sheet Spieler_Teams
A1: Spieler | B1: Fahrer | C1: Stage01 | D1: Stage02 | E1: Stage03 | F1: Stage04 | G1: Stage05
A2: Reto | B2: Ferrand-PrévotPaulineTeam Visma | Lease a Bike | C2: =SUMIF(Ergebnisse_Roh!C$2:C$21,$B2,Punktematrix!$B$2:$B$21) -> 8 | D2: =SUMIF(Ergebnisse_Roh!D$2:D$21,$B2,Punktematrix!$B$2:$B$21) -> 0 | E2: =SUMIF(Ergebnisse_Roh!E$2:E$21,$B2,Punktematrix!$B$2:$B$21) -> 0 | F2: =SUMIF(Ergebnisse_Roh!F$2:F$21,$B2,Punktematrix!$B$2:$B$21) -> 0 | G2: =SUMIF(Ergebnisse_Roh!G$2:G$21,$B2,Punktematrix!$B$2:$B$21) -> 0
A3: Reto | B3: VolleringDemiFDJ United - SUEZ | C3: =SUMIF(Ergebnisse_Roh!C$2:C$21,$B3,Punktematrix!$B$2:$B$21) -> 15 | D3: =SUMIF(Ergebnisse_Roh!D$2:D$21,$B3,Punktematrix!$B$2:$B$21) -> 0 | E3: =SUMIF(Ergebnisse_Roh!E$2:E$21,$B3,Punktematrix!$B$2:$B$21) -> 0 | F3: =SUMIF(Ergebnisse_Roh!F$2:F$21,$B3,Punktematrix!$B$2:$B$21) -> 15 | G3: =SUMIF(Ergebnisse_Roh!G$2:G$21,$B3,Punktematrix!$B$2:$B$21) -> 25
A4: Reto | B4: WiebesLorenaTeam SD Worx - Protime | C4: =SUMIF(Ergebnisse_Roh!C$2:C$21,$B4,Punktematrix!$B$2:$B$21) -> 30 | D4: =SUMIF(Ergebnisse_Roh!D$2:D$21,$B4,Punktematrix!$B$2:$B$21) -> 30 | E4: =SUMIF(Ergebnisse_Roh!E$2:E$21,$B4,Punktematrix!$B$2:$B$21) -> 2 | F4: =SUMIF(Ergebnisse_Roh!F$2:F$21,$B4,Punktematrix!$B$2:$B$21) -> 2 | G4: =SUMIF(Ergebnisse_Roh!G$2:G$21,$B4,Punktematrix!$B$2:$B$21) -> 2
A5: Reto | B5: BlasiPaulaUAE Team L'IMAD | C5: =SUMIF(Ergebnisse_Roh!C$2:C$21,$B5,Punktematrix!$B$2:$B$21) -> 6 | D5: =SUMIF(Ergebnisse_Roh!D$2:D$21,$B5,Punktematrix!$B$2:$B$21) -> 2 | E5: =SUMIF(Ergebnisse_Roh!E$2:E$21,$B5,Punktematrix!$B$2:$B$21) -> 4 | F5: =SUMIF(Ergebnisse_Roh!F$2:F$21,$B5,Punktematrix!$B$2:$B$21) -> 7 | G5: =SUMIF(Ergebnisse_Roh!G$2:G$21,$B5,Punktematrix!$B$2:$B$21) -> 1
A6: Reto | B6: KerbaolCédrineEF Education-Oatly | C6: =SUMIF(Ergebnisse_Roh!C$2:C$21,$B6,Punktematrix!$B$2:$B$21) -> 6 | D6: =SUMIF(Ergebnisse_Roh!D$2:D$21,$B6,Punktematrix!$B$2:$B$21) -> 0 | E6: =SUMIF(Ergebnisse_Roh!E$2:E$21,$B6,Punktematrix!$B$2:$B$21) -> 7 | F6: =SUMIF(Ergebnisse_Roh!F$2:F$21,$B6,Punktematrix!$B$2:$B$21) -> 9 | G6: =SUMIF(Ergebnisse_Roh!G$2:G$21,$B6,Punktematrix!$B$2:$B$21) -> 0
A7: Reto | B7: Le Court-PienaarKimAG Insurance - Soudal Team | C7: =SUMIF(Ergebnisse_Roh!C$2:C$21,$B7,Punktematrix!$B$2:$B$21) -> 20 | D7: =SUMIF(Ergebnisse_Roh!D$2:D$21,$B7,Punktematrix!$B$2:$B$21) -> 0 | E7: =SUMIF(Ergebnisse_Roh!E$2:E$21,$B7,Punktematrix!$B$2:$B$21) -> 11 | F7: =SUMIF(Ergebnisse_Roh!F$2:F$21,$B7,Punktematrix!$B$2:$B$21) -> 0 | G7: =SUMIF(Ergebnisse_Roh!G$2:G$21,$B7,Punktematrix!$B$2:$B$21) -> 4
A8: Reto | B8: KoolCharlotteFenix-Premier Tech | C8: =SUMIF(Ergebnisse_Roh!C$2:C$21,$B8,Punktematrix!$B$2:$B$21) -> 0 | D8: =SUMIF(Ergebnisse_Roh!D$2:D$21,$B8,Punktematrix!$B$2:$B$21) -> 0 | E8: =SUMIF(Ergebnisse_Roh!E$2:E$21,$B8,Punktematrix!$B$2:$B$21) -> 0 | F8: =SUMIF(Ergebnisse_Roh!F$2:F$21,$B8,Punktematrix!$B$2:$B$21) -> 0 | G8: =SUMIF(Ergebnisse_Roh!G$2:G$21,$B8,Punktematrix!$B$2:$B$21) -> 0
A9: Reto | B9: FaulknerKristenEF Education-Oatly | C9: =SUMIF(Ergebnisse_Roh!C$2:C$21,$B9,Punktematrix!$B$2:$B$21) -> 0 | D9: =SUMIF(Ergebnisse_Roh!D$2:D$21,$B9,Punktematrix!$B$2:$B$21) -> 0 | E9: =SUMIF(Ergebnisse_Roh!E$2:E$21,$B9,Punktematrix!$B$2:$B$21) -> 0 | F9: =SUMIF(Ergebnisse_Roh!F$2:F$21,$B9,Punktematrix!$B$2:$B$21) -> 10 | G9: =SUMIF(Ergebnisse_Roh!G$2:G$21,$B9,Punktematrix!$B$2:$B$21) -> 0
A10: Reto | B10: CANYON//SRAM | C10: =SUMIF(Ergebnisse_Roh!C$2:C$21,$B10,Punktematrix!$B$2:$B$21) -> 0 | D10: =SUMIF(Ergebnisse_Roh!D$2:D$21,$B10,Punktematrix!$B$2:$B$21) -> 0 | E10: =SUMIF(Ergebnisse_Roh!E$2:E$21,$B10,Punktematrix!$B$2:$B$21) -> 0 | F10: =SUMIF(Ergebnisse_Roh!F$2:F$21,$B10,Punktematrix!$B$2:$B$21) -> 0 | G10: =SUMIF(Ergebnisse_Roh!G$2:G$21,$B10,Punktematrix!$B$2:$B$21) -> 0
A11: Lanci | B11: VolleringDemiFDJ United - SUEZ | C11: =SUMIF(Ergebnisse_Roh!C$2:C$21,$B11,Punktematrix!$B$2:$B$21) -> 15 | D11: =SUMIF(Ergebnisse_Roh!D$2:D$21,$B11,Punktematrix!$B$2:$B$21) -> 0 | E11: =SUMIF(Ergebnisse_Roh!E$2:E$21,$B11,Punktematrix!$B$2:$B$21) -> 0 | F11: =SUMIF(Ergebnisse_Roh!F$2:F$21,$B11,Punktematrix!$B$2:$B$21) -> 15 | G11: =SUMIF(Ergebnisse_Roh!G$2:G$21,$B11,Punktematrix!$B$2:$B$21) -> 25
A12: Lanci | B12: RüeggNoemiEF Education-Oatly | C12: =SUMIF(Ergebnisse_Roh!C$2:C$21,$B12,Punktematrix!$B$2:$B$21) -> 11 | D12: =SUMIF(Ergebnisse_Roh!D$2:D$21,$B12,Punktematrix!$B$2:$B$21) -> 8 | E12: =SUMIF(Ergebnisse_Roh!E$2:E$21,$B12,Punktematrix!$B$2:$B$21) -> 10 | F12: =SUMIF(Ergebnisse_Roh!F$2:F$21,$B12,Punktematrix!$B$2:$B$21) -> 0 | G12: =SUMIF(Ergebnisse_Roh!G$2:G$21,$B12,Punktematrix!$B$2:$B$21) -> 0
A13: Lanci | B13: NiewiadomaKasiaCANYON//SRAM | C13: =SUMIF(Ergebnisse_Roh!C$2:C$21,$B13,Punktematrix!$B$2:$B$21) -> 9 | D13: =SUMIF(Ergebnisse_Roh!D$2:D$21,$B13,Punktematrix!$B$2:$B$21) -> 0 | E13: =SUMIF(Ergebnisse_Roh!E$2:E$21,$B13,Punktematrix!$B$2:$B$21) -> 0 | F13: =SUMIF(Ergebnisse_Roh!F$2:F$21,$B13,Punktematrix!$B$2:$B$21) -> 3 | G13: =SUMIF(Ergebnisse_Roh!G$2:G$21,$B13,Punktematrix!$B$2:$B$21) -> 15
... A50: Janik | B50: FDJ United - SUEZ | C50: =SUMIF(Ergebnisse_Roh!C$2:C$21,$B50,Punktematrix!$B$2:$B$21) -> 0 | D50: =SUMIF(Ergebnisse_Roh!D$2:D$21,$B50,Punktematrix!$B$2:$B$21) -> 0 | E50: =SUMIF(Ergebnisse_Roh!E$2:E$21,$B50,Punktematrix!$B$2:$B$21) -> 0 | F50: =SUMIF(Ergebnisse_Roh!F$2:F$21,$B50,Punktematrix!$B$2:$B$21) -> 0 | G50: =SUMIF(Ergebnisse_Roh!G$2:G$21,$B50,Punktematrix!$B$2:$B$21) -> 0

Sheet Ergebnisse_Roh
A1: Etappe | B1: Platz | C1: S01 | D1: S02 | E1: S03 | F1: S04 | G1: S05
A2: 1 | B2: 1 | C2: WiebesLorenaTeam SD Worx - Protime | D2: WiebesLorenaTeam SD Worx - Protime | E2: HaugsetSigrid YtterhusUno-X Mobility | F2: ReusserMarlenMovistar Team | G2: VolleringDemiFDJ United - SUEZ
A3: 1 | B3: 2 | C3: Le Court-PienaarKimAG Insurance - Soudal Team | D3: BalsamoElisaLidl - Trek | E3: KopeckyLotteTeam SD Worx - Protime | F3: NooijenLiekeTeam Visma | Lease a Bike | G3: ReusserMarlenMovistar Team
A4: 1 | B4: 3 | C4: VolleringDemiFDJ United - SUEZ | D4: VosMarianneTeam Visma | Lease a Bike | E4: VosMarianneTeam Visma | Lease a Bike | F4: VolleringDemiFDJ United - SUEZ | G4: NiewiadomaKasiaCANYON//SRAM
A5: 1 | B5: 4 | C5: PietersePuckFenix-Premier Tech | D5: BossuytShariAG Insurance - Soudal Team | E5: OstolazaUsoaLaboral Kutxa - Fundación Euskadi | F5: BäckstedtZoeCANYON//SRAM | G5: WłodarczykDominikaUAE Team L'IMAD
A6: 1 | B6: 5 | C6: RüeggNoemiEF Education-Oatly | D6: PaternosterLetiziaLiv AlUla Jayco | E6: Le Court-PienaarKimAG Insurance - Soudal Team | F6: BredewoldMischaTeam SD Worx - Protime | G6: HolmgrenIsabellaLidl - Trek
A7: 1 | B7: 6 | C7: Longo BorghiniElisaUAE Team L'IMAD | D7: BäckstedtZoeCANYON//SRAM | E7: RüeggNoemiEF Education-Oatly | F7: FaulknerKristenEF Education-Oatly | G7: NiedermaierAntoniaCANYON//SRAM
A8: 1 | B8: 7 | C8: NiewiadomaKasiaCANYON//SRAM | D8: NelsonJosieTeam Picnic PostNL | E8: GeryCéliaFDJ United - SUEZ | F8: KerbaolCédrineEF Education-Oatly | G8: VinkeNienkeTeam SD Worx - Protime
A9: 1 | B9: 8 | C9: Ferrand-PrévotPaulineTeam Visma | Lease a Bike | D9: RüeggNoemiEF Education-Oatly | E9: MulMalwinaCofidis Women Team | F9: MarkusRiejanneLidl - Trek | G9: de VriesFemkeTeam Visma | Lease a Bike
A10: 1 | B10: 9 | C10: ReusserMarlenMovistar Team | D10: MulMalwinaCofidis Women Team | E10: KerbaolCédrineEF Education-Oatly | F10: ClaesLotteFenix-Premier Tech | G10: Fisher-BlackNiamhLidl - Trek
A11: 1 | B11: 10 | C11: KerbaolCédrineEF Education-Oatly | D11: RiedmannLindaLotto Intermarché Ladies | E11: Trinca ColonelMonicaLiv AlUla Jayco | F11: Longo BorghiniElisaUAE Team L'IMAD | G11: de JongThalitaHuman Powered Health
A12: 1 | B12: 11 | C12: Fisher-BlackNiamhLidl - Trek | D12: JansenElineVolkerWessels Cycling Team | E12: WłodarczykDominikaUAE Team L'IMAD | F12: BlasiPaulaUAE Team L'IMAD | G12: PietersePuckFenix-Premier Tech
A13: 1 | B13: 12 | C13: BlasiPaulaUAE Team L'IMAD | D13: WilliamsLilyHuman Powered Health | E13: MarkusRiejanneLidl - Trek | F13: CouzensMillieFenix-Premier Tech | G13: Le Court-PienaarKimAG Insurance - Soudal Team
... A16: 1 | B16: 15 | C16: GarcíaMaviUAE Team L'IMAD | D16: CouzensMillieFenix-Premier Tech | E16: PietersePuckFenix-Premier Tech | F16: de VriesFemkeTeam Visma | Lease a Bike | G16: BlasiPaulaUAE Team L'IMAD
A17: 1 | B17: Gelb | C17: WiebesLorenaTeam SD Worx - Protime | D17: WiebesLorenaTeam SD Worx - Protime | E17: HaugsetSigrid YtterhusUno-X Mobility | F17: ReusserMarlenMovistar Team | G17: ReusserMarlenMovistar Team
A18: 1 | B18: Grün | C18: WiebesLorenaTeam SD Worx - Protime | D18: WiebesLorenaTeam SD Worx - Protime | E18: WiebesLorenaTeam SD Worx - Protime | F18: WiebesLorenaTeam SD Worx - Protime | G18: WiebesLorenaTeam SD Worx - Protime
A19: 1 | B19: Weiß | C19: BlasiPaulaUAE Team L'IMAD | D19: BlasiPaulaUAE Team L'IMAD | E19: BlasiPaulaUAE Team L'IMAD | F19: BlasiPaulaUAE Team L'IMAD | G19: NiedermaierAntoniaCANYON//SRAM
A20: 1 | B20: Berg | C20: MahéOcéaneMa Petite Entreprise | D20: MahéOcéaneMa Petite Entreprise | E20: PietersePuckFenix-Premier Tech | F20: PietersePuckFenix-Premier Tech | G20: PietersePuckFenix-Premier Tech
A21: 1 | B21: Mannschaft | C21: UAE Team L'IMAD | D21: EF Education-Oatly | E21: Team SD Worx - Protime | F21: Team Visma | Lease a Bike | G21: Lidl - Trek

Sheet Startlist2026
A1: BIB | B1: Specialty | C1: Age | D1: Rider | E1: Team | F1: S01 | G1: S02 | H1: S03 | I1: S04 | J1: S05
A2: 1 | B2: Classic | C2: 34 | D2: Ferrand-PrévotPaulineTeam Visma | Lease a Bike | E2: Team Visma | Lease a Bike | F2: =SUMIF(Ergebnisse_Roh!C$2:C$21,$D2,Punktematrix!$B$2:$B$21) -> 8 | G2: =SUMIF(Ergebnisse_Roh!D$2:D$21,$D2,Punktematrix!$B$2:$B$21) -> 0 | H2: =SUMIF(Ergebnisse_Roh!E$2:E$21,$D2,Punktematrix!$B$2:$B$21) -> 0 | I2: =SUMIF(Ergebnisse_Roh!F$2:F$21,$D2,Punktematrix!$B$2:$B$21) -> 0 | J2: =SUMIF(Ergebnisse_Roh!G$2:G$21,$D2,Punktematrix!$B$2:$B$21) -> 0
A3: 2 | B3: GC | C3: 21 | D3: BunelMarionTeam Visma | Lease a Bike | E3: Team Visma | Lease a Bike | F3: =SUMIF(Ergebnisse_Roh!C$2:C$21,$D3,Punktematrix!$B$2:$B$21) -> 0 | G3: =SUMIF(Ergebnisse_Roh!D$2:D$21,$D3,Punktematrix!$B$2:$B$21) -> 0 | H3: =SUMIF(Ergebnisse_Roh!E$2:E$21,$D3,Punktematrix!$B$2:$B$21) -> 0 | I3: =SUMIF(Ergebnisse_Roh!F$2:F$21,$D3,Punktematrix!$B$2:$B$21) -> 0 | J3: =SUMIF(Ergebnisse_Roh!G$2:G$21,$D3,Punktematrix!$B$2:$B$21) -> 0
A4: 3 | B4: GC | C4: 32 | D4: de VriesFemkeTeam Visma | Lease a Bike | E4: Team Visma | Lease a Bike | F4: =SUMIF(Ergebnisse_Roh!C$2:C$21,$D4,Punktematrix!$B$2:$B$21) -> 0 | G4: =SUMIF(Ergebnisse_Roh!D$2:D$21,$D4,Punktematrix!$B$2:$B$21) -> 0 | H4: =SUMIF(Ergebnisse_Roh!E$2:E$21,$D4,Punktematrix!$B$2:$B$21) -> 0 | I4: =SUMIF(Ergebnisse_Roh!F$2:F$21,$D4,Punktematrix!$B$2:$B$21) -> 1 | J4: =SUMIF(Ergebnisse_Roh!G$2:G$21,$D4,Punktematrix!$B$2:$B$21) -> 8
A5: 4 | B5: TT | C5: 23 | D5: HengeveldDaniekTeam Visma | Lease a Bike | E5: Team Visma | Lease a Bike | F5: =SUMIF(Ergebnisse_Roh!C$2:C$21,$D5,Punktematrix!$B$2:$B$21) -> 0 | G5: =SUMIF(Ergebnisse_Roh!D$2:D$21,$D5,Punktematrix!$B$2:$B$21) -> 0 | H5: =SUMIF(Ergebnisse_Roh!E$2:E$21,$D5,Punktematrix!$B$2:$B$21) -> 0 | I5: =SUMIF(Ergebnisse_Roh!F$2:F$21,$D5,Punktematrix!$B$2:$B$21) -> 0 | J5: =SUMIF(Ergebnisse_Roh!G$2:G$21,$D5,Punktematrix!$B$2:$B$21) -> 0
A6: 5 | B6: TT | C6: 25 | D6: NooijenLiekeTeam Visma | Lease a Bike | E6: Team Visma | Lease a Bike | F6: =SUMIF(Ergebnisse_Roh!C$2:C$21,$D6,Punktematrix!$B$2:$B$21) -> 0 | G6: =SUMIF(Ergebnisse_Roh!D$2:D$21,$D6,Punktematrix!$B$2:$B$21) -> 0 | H6: =SUMIF(Ergebnisse_Roh!E$2:E$21,$D6,Punktematrix!$B$2:$B$21) -> 0 | I6: =SUMIF(Ergebnisse_Roh!F$2:F$21,$D6,Punktematrix!$B$2:$B$21) -> 20 | J6: =SUMIF(Ergebnisse_Roh!G$2:G$21,$D6,Punktematrix!$B$2:$B$21) -> 0
A7: 6 | B7: Hills | C7: 24 | D7: Van DamSarahTeam Visma | Lease a Bike | E7: Team Visma | Lease a Bike | F7: =SUMIF(Ergebnisse_Roh!C$2:C$21,$D7,Punktematrix!$B$2:$B$21) -> 0 | G7: =SUMIF(Ergebnisse_Roh!D$2:D$21,$D7,Punktematrix!$B$2:$B$21) -> 0 | H7: =SUMIF(Ergebnisse_Roh!E$2:E$21,$D7,Punktematrix!$B$2:$B$21) -> 0 | I7: =SUMIF(Ergebnisse_Roh!F$2:F$21,$D7,Punktematrix!$B$2:$B$21) -> 0 | J7: =SUMIF(Ergebnisse_Roh!G$2:G$21,$D7,Punktematrix!$B$2:$B$21) -> 0
A8: 7 | B8: Classic | C8: 39 | D8: VosMarianneTeam Visma | Lease a Bike | E8: Team Visma | Lease a Bike | F8: =SUMIF(Ergebnisse_Roh!C$2:C$21,$D8,Punktematrix!$B$2:$B$21) -> 0 | G8: =SUMIF(Ergebnisse_Roh!D$2:D$21,$D8,Punktematrix!$B$2:$B$21) -> 15 | H8: =SUMIF(Ergebnisse_Roh!E$2:E$21,$D8,Punktematrix!$B$2:$B$21) -> 15 | I8: =SUMIF(Ergebnisse_Roh!F$2:F$21,$D8,Punktematrix!$B$2:$B$21) -> 0 | J8: =SUMIF(Ergebnisse_Roh!G$2:G$21,$D8,Punktematrix!$B$2:$B$21) -> 0
A9: 11 | B9: Classic | C9: 29 | D9: VolleringDemiFDJ United - SUEZ | E9: FDJ United - SUEZ | F9: =SUMIF(Ergebnisse_Roh!C$2:C$21,$D9,Punktematrix!$B$2:$B$21) -> 15 | G9: =SUMIF(Ergebnisse_Roh!D$2:D$21,$D9,Punktematrix!$B$2:$B$21) -> 0 | H9: =SUMIF(Ergebnisse_Roh!E$2:E$21,$D9,Punktematrix!$B$2:$B$21) -> 0 | I9: =SUMIF(Ergebnisse_Roh!F$2:F$21,$D9,Punktematrix!$B$2:$B$21) -> 15 | J9: =SUMIF(Ergebnisse_Roh!G$2:G$21,$D9,Punktematrix!$B$2:$B$21) -> 25
A10: 12 | B10: GC | C10: 27 | D10: BerthetJulietteFDJ United - SUEZ | E10: FDJ United - SUEZ | F10: =SUMIF(Ergebnisse_Roh!C$2:C$21,$D10,Punktematrix!$B$2:$B$21) -> 0 | G10: =SUMIF(Ergebnisse_Roh!D$2:D$21,$D10,Punktematrix!$B$2:$B$21) -> 0 | H10: =SUMIF(Ergebnisse_Roh!E$2:E$21,$D10,Punktematrix!$B$2:$B$21) -> 0 | I10: =SUMIF(Ergebnisse_Roh!F$2:F$21,$D10,Punktematrix!$B$2:$B$21) -> 0 | J10: =SUMIF(Ergebnisse_Roh!G$2:G$21,$D10,Punktematrix!$B$2:$B$21) -> 3
A11: 13 | B11: Classic | C11: 20 | D11: GeryCéliaFDJ United - SUEZ | E11: FDJ United - SUEZ | F11: =SUMIF(Ergebnisse_Roh!C$2:C$21,$D11,Punktematrix!$B$2:$B$21) -> 0 | G11: =SUMIF(Ergebnisse_Roh!D$2:D$21,$D11,Punktematrix!$B$2:$B$21) -> 2 | H11: =SUMIF(Ergebnisse_Roh!E$2:E$21,$D11,Punktematrix!$B$2:$B$21) -> 9 | I11: =SUMIF(Ergebnisse_Roh!F$2:F$21,$D11,Punktematrix!$B$2:$B$21) -> 0 | J11: =SUMIF(Ergebnisse_Roh!G$2:G$21,$D11,Punktematrix!$B$2:$B$21) -> 0
A12: 14 | B12: Classic | C12: 26 | D12: KochFranziskaFDJ United - SUEZ | E12: FDJ United - SUEZ | F12: =SUMIF(Ergebnisse_Roh!C$2:C$21,$D12,Punktematrix!$B$2:$B$21) -> 0 | G12: =SUMIF(Ergebnisse_Roh!D$2:D$21,$D12,Punktematrix!$B$2:$B$21) -> 0 | H12: =SUMIF(Ergebnisse_Roh!E$2:E$21,$D12,Punktematrix!$B$2:$B$21) -> 0 | I12: =SUMIF(Ergebnisse_Roh!F$2:F$21,$D12,Punktematrix!$B$2:$B$21) -> 0 | J12: =SUMIF(Ergebnisse_Roh!G$2:G$21,$D12,Punktematrix!$B$2:$B$21) -> 0
A13: 15 | B13: Hills | C13: 32 | D13: KraakAmberFDJ United - SUEZ | E13: FDJ United - SUEZ | F13: =SUMIF(Ergebnisse_Roh!C$2:C$21,$D13,Punktematrix!$B$2:$B$21) -> 0 | G13: =SUMIF(Ergebnisse_Roh!D$2:D$21,$D13,Punktematrix!$B$2:$B$21) -> 0 | H13: =SUMIF(Ergebnisse_Roh!E$2:E$21,$D13,Punktematrix!$B$2:$B$21) -> 0 | I13: =SUMIF(Ergebnisse_Roh!F$2:F$21,$D13,Punktematrix!$B$2:$B$21) -> 0 | J13: =SUMIF(Ergebnisse_Roh!G$2:G$21,$D13,Punktematrix!$B$2:$B$21) -> 0
... A147: 207 | B147: Classic | C147: 28 | D147: ValentinConstanceMayenne Monbana My Pie | E147: Mayenne Monbana My Pie | F147: =SUMIF(Ergebnisse_Roh!C$2:C$21,$D147,Punktematrix!$B$2:$B$21) -> 0 | G147: =SUMIF(Ergebnisse_Roh!D$2:D$21,$D147,Punktematrix!$B$2:$B$21) -> 0 | H147: =SUMIF(Ergebnisse_Roh!E$2:E$21,$D147,Punktematrix!$B$2:$B$21) -> 0 | I147: =SUMIF(Ergebnisse_Roh!F$2:F$21,$D147,Punktematrix!$B$2:$B$21) -> 0 | J147: =SUMIF(Ergebnisse_Roh!G$2:G$21,$D147,Punktematrix!$B$2:$B$21) -> 0
D148: Team Visma | Lease a Bike | F148: =SUMIF(Ergebnisse_Roh!C$2:C$21,$D148,Punktematrix!$B$2:$B$21) -> 0 | G148: =SUMIF(Ergebnisse_Roh!D$2:D$21,$D148,Punktematrix!$B$2:$B$21) -> 0 | H148: =SUMIF(Ergebnisse_Roh!E$2:E$21,$D148,Punktematrix!$B$2:$B$21) -> 0 | I148: =SUMIF(Ergebnisse_Roh!F$2:F$21,$D148,Punktematrix!$B$2:$B$21) -> 2 | J148: =SUMIF(Ergebnisse_Roh!G$2:G$21,$D148,Punktematrix!$B$2:$B$21) -> 0
D149: FDJ United - SUEZ | F149: =SUMIF(Ergebnisse_Roh!C$2:C$21,$D149,Punktematrix!$B$2:$B$21) -> 0 | G149: =SUMIF(Ergebnisse_Roh!D$2:D$21,$D149,Punktematrix!$B$2:$B$21) -> 0 | H149: =SUMIF(Ergebnisse_Roh!E$2:E$21,$D149,Punktematrix!$B$2:$B$21) -> 0 | I149: =SUMIF(Ergebnisse_Roh!F$2:F$21,$D149,Punktematrix!$B$2:$B$21) -> 0 | J149: =SUMIF(Ergebnisse_Roh!G$2:G$21,$D149,Punktematrix!$B$2:$B$21) -> 0
D150: CANYON//SRAM | F150: =SUMIF(Ergebnisse_Roh!C$2:C$21,$D150,Punktematrix!$B$2:$B$21) -> 0 | G150: =SUMIF(Ergebnisse_Roh!D$2:D$21,$D150,Punktematrix!$B$2:$B$21) -> 0 | H150: =SUMIF(Ergebnisse_Roh!E$2:E$21,$D150,Punktematrix!$B$2:$B$21) -> 0 | I150: =SUMIF(Ergebnisse_Roh!F$2:F$21,$D150,Punktematrix!$B$2:$B$21) -> 0 | J150: =SUMIF(Ergebnisse_Roh!G$2:G$21,$D150,Punktematrix!$B$2:$B$21) -> 0
D151: UAE Team L'IMAD | F151: =SUMIF(Ergebnisse_Roh!C$2:C$21,$D151,Punktematrix!$B$2:$B$21) -> 2 | G151: =SUMIF(Ergebnisse_Roh!D$2:D$21,$D151,Punktematrix!$B$2:$B$21) -> 0 | H151: =SUMIF(Ergebnisse_Roh!E$2:E$21,$D151,Punktematrix!$B$2:$B$21) -> 0 | I151: =SUMIF(Ergebnisse_Roh!F$2:F$21,$D151,Punktematrix!$B$2:$B$21) -> 0 | J151: =SUMIF(Ergebnisse_Roh!G$2:G$21,$D151,Punktematrix!$B$2:$B$21) -> 0
D152: Team SD Worx - Protime | F152: =SUMIF(Ergebnisse_Roh!C$2:C$21,$D152,Punktematrix!$B$2:$B$21) -> 0 | G152: =SUMIF(Ergebnisse_Roh!D$2:D$21,$D152,Punktematrix!$B$2:$B$21) -> 0 | H152: =SUMIF(Ergebnisse_Roh!E$2:E$21,$D152,Punktematrix!$B$2:$B$21) -> 2 | I152: =SUMIF(Ergebnisse_Roh!F$2:F$21,$D152,Punktematrix!$B$2:$B$21) -> 0 | J152: =SUMIF(Ergebnisse_Roh!G$2:G$21,$D152,Punktematrix!$B$2:$B$21) -> 0
D153: Movistar Team | F153: =SUMIF(Ergebnisse_Roh!C$2:C$21,$D153,Punktematrix!$B$2:$B$21) -> 0 | G153: =SUMIF(Ergebnisse_Roh!D$2:D$21,$D153,Punktematrix!$B$2:$B$21) -> 0 | H153: =SUMIF(Ergebnisse_Roh!E$2:E$21,$D153,Punktematrix!$B$2:$B$21) -> 0 | I153: =SUMIF(Ergebnisse_Roh!F$2:F$21,$D153,Punktematrix!$B$2:$B$21) -> 0 | J153: =SUMIF(Ergebnisse_Roh!G$2:G$21,$D153,Punktematrix!$B$2:$B$21) -> 0
D154: Lidl - Trek | F154: =SUMIF(Ergebnisse_Roh!C$2:C$21,$D154,Punktematrix!$B$2:$B$21) -> 0 | G154: =SUMIF(Ergebnisse_Roh!D$2:D$21,$D154,Punktematrix!$B$2:$B$21) -> 0 | H154: =SUMIF(Ergebnisse_Roh!E$2:E$21,$D154,Punktematrix!$B$2:$B$21) -> 0 | I154: =SUMIF(Ergebnisse_Roh!F$2:F$21,$D154,Punktematrix!$B$2:$B$21) -> 0 | J154: =SUMIF(Ergebnisse_Roh!G$2:G$21,$D154,Punktematrix!$B$2:$B$21) -> 2
D155: AG Insurance - Soudal Team | F155: =SUMIF(Ergebnisse_Roh!C$2:C$21,$D155,Punktematrix!$B$2:$B$21) -> 0 | G155: =SUMIF(Ergebnisse_Roh!D$2:D$21,$D155,Punktematrix!$B$2:$B$21) -> 0 | H155: =SUMIF(Ergebnisse_Roh!E$2:E$21,$D155,Punktematrix!$B$2:$B$21) -> 0 | I155: =SUMIF(Ergebnisse_Roh!F$2:F$21,$D155,Punktematrix!$B$2:$B$21) -> 0 | J155: =SUMIF(Ergebnisse_Roh!G$2:G$21,$D155,Punktematrix!$B$2:$B$21) -> 0
D156: EF Education-Oatly | F156: =SUMIF(Ergebnisse_Roh!C$2:C$21,$D156,Punktematrix!$B$2:$B$21) -> 0 | G156: =SUMIF(Ergebnisse_Roh!D$2:D$21,$D156,Punktematrix!$B$2:$B$21) -> 2 | H156: =SUMIF(Ergebnisse_Roh!E$2:E$21,$D156,Punktematrix!$B$2:$B$21) -> 0 | I156: =SUMIF(Ergebnisse_Roh!F$2:F$21,$D156,Punktematrix!$B$2:$B$21) -> 0 | J156: =SUMIF(Ergebnisse_Roh!G$2:G$21,$D156,Punktematrix!$B$2:$B$21) -> 0
D157: Fenix-Premier Tech | F157: =SUMIF(Ergebnisse_Roh!C$2:C$21,$D157,Punktematrix!$B$2:$B$21) -> 0 | G157: =SUMIF(Ergebnisse_Roh!D$2:D$21,$D157,Punktematrix!$B$2:$B$21) -> 0 | H157: =SUMIF(Ergebnisse_Roh!E$2:E$21,$D157,Punktematrix!$B$2:$B$21) -> 0 | I157: =SUMIF(Ergebnisse_Roh!F$2:F$21,$D157,Punktematrix!$B$2:$B$21) -> 0 | J157: =SUMIF(Ergebnisse_Roh!G$2:G$21,$D157,Punktematrix!$B$2:$B$21) -> 0
D158: Human Powered Health | F158: =SUMIF(Ergebnisse_Roh!C$2:C$21,$D158,Punktematrix!$B$2:$B$21) -> 0 | G158: =SUMIF(Ergebnisse_Roh!D$2:D$21,$D158,Punktematrix!$B$2:$B$21) -> 0 | H158: =SUMIF(Ergebnisse_Roh!E$2:E$21,$D158,Punktematrix!$B$2:$B$21) -> 0 | I158: =SUMIF(Ergebnisse_Roh!F$2:F$21,$D158,Punktematrix!$B$2:$B$21) -> 0 | J158: =SUMIF(Ergebnisse_Roh!G$2:G$21,$D158,Punktematrix!$B$2:$B$21) -> 0
D159: Liv AlUla Jayco | F159: =SUMIF(Ergebnisse_Roh!C$2:C$21,$D159,Punktematrix!$B$2:$B$21) -> 0 | G159: =SUMIF(Ergebnisse_Roh!D$2:D$21,$D159,Punktematrix!$B$2:$B$21) -> 0 | H159: =SUMIF(Ergebnisse_Roh!E$2:E$21,$D159,Punktematrix!$B$2:$B$21) -> 0 | I159: =SUMIF(Ergebnisse_Roh!F$2:F$21,$D159,Punktematrix!$B$2:$B$21) -> 0 | J159: =SUMIF(Ergebnisse_Roh!G$2:G$21,$D159,Punktematrix!$B$2:$B$21) -> 0
... D168: Mayenne Monbana My Pie | F168: =SUMIF(Ergebnisse_Roh!C$2:C$21,$D168,Punktematrix!$B$2:$B$21) -> 0 | G168: =SUMIF(Ergebnisse_Roh!D$2:D$21,$D168,Punktematrix!$B$2:$B$21) -> 0 | H168: =SUMIF(Ergebnisse_Roh!E$2:E$21,$D168,Punktematrix!$B$2:$B$21) -> 0 | I168: =SUMIF(Ergebnisse_Roh!F$2:F$21,$D168,Punktematrix!$B$2:$B$21) -> 0 | J168: =SUMIF(Ergebnisse_Roh!G$2:G$21,$D168,Punktematrix!$B$2:$B$21) -> 0

Sheet Punktematrix
A1: Platz | B1: Punkte | C1: GC | D1: Mountain | E1: Sprint | F1: Youth | G1: TeamRank
A2: 1 | B2: 25 | C2: 75 | D2: 20 | E2: 20 | F2: 15 | G2: 30
A3: 2 | B3: 20 | C3: 70 | D3: 18 | E3: 18 | F3: 10 | G3: 25
A4: 3 | B4: 15 | C4: 65 | D4: 16 | E4: 16 | F4: 5 | G4: 20
A5: 4 | B5: 12 | C5: 60 | D5: 14 | E5: 14
A6: 5 | B6: 11 | C6: 55 | D6: 12 | E6: 12
A7: 6 | B7: 10 | C7: 50 | D7: 10 | E7: 10
A8: 7 | B8: 9 | C8: 45 | D8: 8 | E8: 8
A9: 8 | B9: 8 | C9: 40 | D9: 6 | E9: 6
A10: 9 | B10: 7 | C10: 35 | D10: 4 | E10: 4
A11: 10 | B11: 6 | C11: 30 | D11: 2 | E11: 2
A12: 11 | B12: 5 | C12: 25
A13: 12 | B13: 4 | C13: 20
A14: 13 | B14: 3 | C14: 15
A15: 14 | B15: 2 | C15: 10
A16: 15 | B16: 1 | C16: 5
A17: Gelb | B17: 3
A18: Grün | B18: 2
A19: Weiß | B19: 2
A20: Berg | B20: 2
A21: Mannschaft | B21: 2

Sheet S01
A1: 1 | B1: 1 | C1: +0:00 | D1: 47 | F1: Sprint | G1: 27 | H1: WiebesLorenaTeam SD Worx - Protime | I1: Team SD Worx - Protime | J1: 210 | K1: 50 | L1: 10″ | M1: 3:29:113:29:11
A2: 2 | B2: 2 | C2: +0:04 | D2: 71 | F2: Classic | G2: 30 | H2: Le Court-PienaarKimAG Insurance - Soudal Team | I2: AG Insurance - Soudal Team | J2: 150 | K2: 30 | L2: 6″ | M2: ,,0:00
A3: 3 | B3: 3 | C3: +0:06 | D3: 11 | F3: Classic | G3: 29 | H3: VolleringDemiFDJ United - SUEZ | I3: FDJ United - SUEZ | J3: 110 | K3: 18 | L3: 4″ | M3: ,,0:00
A4: 4 | B4: 4 | C4: +0:10 | D4: 91 | F4: Classic | G4: 24 | H4: PietersePuckFenix-Premier Tech | I4: Fenix-Premier Tech | J4: 90 | K4: 13 | M4: ,,0:00
A5: 5 | B5: 5 | C5: +0:10 | D5: 86 | F5: Classic | G5: 25 | H5: RüeggNoemiEF Education-Oatly | I5: EF Education-Oatly | J5: 70 | K5: 10 | M5: ,,0:00
A6: 6 | B6: 6 | C6: +0:10 | D6: 35 | F6: Classic | G6: 34 | H6: Longo BorghiniElisaUAE Team L'IMAD | I6: UAE Team L'IMAD | J6: 55 | K6: 7 | M6: ,,0:00
A7: 7 | B7: 7 | C7: +0:10 | D7: 21 | F7: Classic | G7: 31 | H7: NiewiadomaKasiaCANYON//SRAM | I7: CANYON//SRAM | J7: 45 | K7: 4 | M7: ,,0:00
A8: 8 | B8: 8 | C8: +0:10 | D8: 1 | F8: Classic | G8: 34 | H8: Ferrand-PrévotPaulineTeam Visma | Lease a Bike | I8: Team Visma | Lease a Bike | J8: 40 | K8: 3 | M8: ,,0:00
A9: 9 | B9: 9 | C9: +0:10 | D9: 85 | F9: Hills | G9: 25 | H9: ReusserMarlenMovistar Team | I9: EF Education-Oatly | J9: 35 | K9: 2 | M9: ,,0:00
A10: 10 | B10: 10 | C10: +0:10 | D10: 51 | F10: TT | G10: 34 | H10: KerbaolCédrineEF Education-Oatly | I10: Movistar Team | J10: 30 | K10: 1 | M10: ,,0:00
A11: 11 | B11: 11 | C11: +0:15 | D11: 64 | F11: GC | G11: 25 | H11: Fisher-BlackNiamhLidl - Trek | I11: Lidl - Trek | J11: 25 | M11: 0:050:05
A12: 12 | B12: 12 | C12: +0:18 | D12: 32 | F12: Classic | G12: 23 | H12: BlasiPaulaUAE Team L'IMAD | I12: UAE Team L'IMAD | J12: 20 | M12: 0:080:08
A13: 13 | B13: 13 | C13: +0:18 | D13: 41 | F13: Classic | G13: 36 | H13: van der BreggenAnnaTeam SD Worx - Protime | I13: Team SD Worx - Protime | J13: 15 | M13: ,,0:08
A14: 14 | B14: 14 | C14: +0:18 | D14: 65 | F14: Climber | G14: 21 | H14: HolmgrenIsabellaLidl - Trek | I14: Lidl - Trek | J14: 10 | M14: ,,0:08
A15: 15 | B15: 15 | C15: +0:18 | D15: 34 | F15: Hills | G15: 42 | H15: GarcíaMaviUAE Team L'IMAD | I15: UAE Team L'IMAD | J15: 5 | M15: ,,0:08
A16: 16 | B16: 16 | C16: +0:18 | D16: 12 | F16: GC | G16: 27 | H16: BerthetJulietteFDJ United - SUEZ | I16: FDJ United - SUEZ | M16: ,,0:08
A17: 17 | B17: 17 | C17: +0:18 | D17: 25 | F17: GC | G17: 23 | H17: NiedermaierAntoniaCANYON//SRAM | I17: CANYON//SRAM | M17: ,,0:08
A18: 18 | B18: 18 | C18: +0:18 | D18: 7 | F18: Classic | G18: 39 | H18: VosMarianneTeam Visma | Lease a Bike | I18: Team Visma | Lease a Bike | M18: ,,0:08
A19: 19 | B19: 19 | C19: +0:26 | D19: 131 | F19: Hills | G19: 29 | H19: MorierÉmilieSt Michel - Preference Home - Auber93 | I19: St Michel - Preference Home - Auber93 | M19: 0:160:16
A20: 20 | B20: 20 | C20: +0:26 | D20: 111 | F20: Hills | G20: 27 | H20: Trinca ColonelMonicaLiv AlUla Jayco | I20: Liv AlUla Jayco | M20: ,,0:16
A21: 21 | B21: 21 | C21: +0:26 | D21: 104 | F21: TT | G21: 32 | H21: de JongThalitaHuman Powered Health | I21: Human Powered Health | M21: ,,0:16
A22: 22 | B22: 22 | C22: +0:29 | D22: 141 | F22: Hills | G22: 22 | H22: MulMalwinaCofidis Women Team | I22: Cofidis Women Team | M22: 0:190:19
A23: 23 | B23: 23 | C23: +0:29 | D23: 95 | F23: GC | G23: 28 | H23: KastelijnYaraFenix-Premier Tech | I23: Fenix-Premier Tech | M23: ,,0:19
A24: 24 | B24: 24 | C24: +0:29 | D24: 151 | F24: Hills | G24: 28 | H24: OstolazaUsoaLaboral Kutxa - Fundación Euskadi | I24: Laboral Kutxa - Fundación Euskadi | M24: ,,0:19
A25: 25 | B25: 25 | C25: +0:32 | D25: 124 | F25: Classic | G25: 25 | H25: GeorgiPfeifferTeam Picnic PostNL | I25: Team Picnic PostNL | M25: 0:220:22
A26: 26 | B26: 26 | C26: +0:32 | D26: 77 | F26: GC | G26: 29 | H26: ŽigartUrškaAG Insurance - Soudal Team | I26: AG Insurance - Soudal Team | M26: ,,0:22
A27: 27 | B27: 27 | C27: +0:32 | D27: 13 | F27: Classic | G27: 20 | H27: GeryCéliaFDJ United - SUEZ | I27: FDJ United - SUEZ | M27: ,,0:22
... A70: 70 | B70: 70 | C70: +1:55 | D70: 84 | F70: Classic | G70: 33 | H70: FaulknerKristenEF Education-Oatly | I70: EF Education-Oatly | M70: 1:451:45
A71: 72 | D71: 57 | F71: Classic | G71: 33 | H71: SierraArlenisMovistar Team | I71: Movistar Team | M71: 1:561:56
A72: 73 | D72: 203 | F72: Hills | G72: 25 | H72: CoutinhoAliceMayenne Monbana My Pie | I72: Mayenne Monbana My Pie | M72: ,,1:56
A73: 74 | D73: 73 | F73: Hills | G73: 27 | H73: BorghesiLetiziaAG Insurance - Soudal Team | I73: AG Insurance - Soudal Team | M73: 2:142:14
A74: 75 | D74: 72 | F74: Hills | G74: 29 | H74: BenitoMireiaAG Insurance - Soudal Team | I74: AG Insurance - Soudal Team | M74: ,,2:14
A75: 76 | D75: 165 | F75: TT | G75: 24 | H75: MolenaarLauraVolkerWessels Cycling Team | I75: VolkerWessels Cycling Team | M75: ,,2:14
A76: 77 | D76: 17 | F76: Hills | G76: 27 | H76: MuzicÉvitaFDJ United - SUEZ | I76: FDJ United - SUEZ | M76: 2:172:17
A77: 78 | D77: 23 | F77: Sprint | G77: 27 | H77: ConsonniChiaraCANYON//SRAM | I77: CANYON//SRAM | M77: ,,2:17
A78: 79 | D78: 106 | F78: Classic | G78: 27 | H78: RaaijmakersMaritHuman Powered Health | I78: Human Powered Health | M78: ,,2:17
A79: 80 | D79: 127 | F79: Hills | G79: 24 | H79: NelsonJosieTeam Picnic PostNL | I79: Team Picnic PostNL | M79: 2:252:25
A80: 81 | D80: 191 | F80: Climber | G80: 22 | H80: LatimierClémenceMa Petite Entreprise | I80: Ma Petite Entreprise | M80: 2:382:38
A81: 82 | D81: 82 | F81: Classic | G81: 24 | H81: BertonNinaEF Education-Oatly | I81: EF Education-Oatly | M81: 2:442:44
A82: 83 | D82: 66 | F82: TT | G82: 31 | H82: MarkusRiejanneLidl - Trek | I82: Lidl - Trek | M82: 2:462:46
...

Sheet Tabelle8
A1: Rnk | B1: GC | C1: Timelag | D1: BIB | E1: H2H | F1: Specialty | G1: Age | H1: Rider | I1: Team | J1: UCI | K1: Pnt | M1: Time
A2: 1 | B2: 1 | C2: +0:00 | D2: 47 | F2: Sprint | G2: 27 | H2: WiebesLorenaTeam SD Worx - Protime | I2: Team SD Worx - Protime | J2: 210 | K2: 50 | L2: 10″ | M2: 3:42:083:42:08
A3: 2 | B3: 32 | C3: +0:51 | D3: 61 | F3: Classic | G3: 28 | H3: BalsamoElisaLidl - Trek | I3: Lidl - Trek | J3: 150 | K3: 30 | L3: 6″ | M3: ,,0:00
A4: 3 | B4: 11 | C4: +0:24 | D4: 7 | F4: Classic | G4: 39 | H4: VosMarianneTeam Visma | Lease a Bike | I4: Team Visma | Lease a Bike | J4: 110 | K4: 18 | L4: 4″ | M4: ,,0:00
A5: 4 | B5: 76 | C5: +4:23 | D5: 74 | F5: Sprint | G5: 25 | H5: BossuytShariAG Insurance - Soudal Team | I5: AG Insurance - Soudal Team | J5: 90 | K5: 13 | M5: ,,0:00
A6: 5 | B6: 71 | C6: +3:44 | D6: 115 | F6: Classic | G6: 27 | H6: PaternosterLetiziaLiv AlUla Jayco | I6: Liv AlUla Jayco | J6: 70 | K6: 10 | M6: ,,0:00
A7: 6 | B7: 61 | C7: +2:45 | D7: 127 | F7: Hills | G7: 24 | H7: BäckstedtZoeCANYON//SRAM | I7: Team Picnic PostNL | J7: 55 | K7: 7 | M7: ,,0:00
A8: 7 | B8: 33 | C8: +0:57 | D8: 22 | F8: TT | G8: 21 | H8: NelsonJosieTeam Picnic PostNL | I8: CANYON//SRAM | J8: 45 | K8: 4 | M8: ,,0:00
A9: 8 | B9: 4 | C9: +0:20 | D9: 86 | F9: Classic | G9: 25 | H9: RüeggNoemiEF Education-Oatly | I9: EF Education-Oatly | J9: 40 | K9: 3 | M9: ,,0:00
A10: 9 | B10: 22 | C10: +0:39 | D10: 141 | F10: Hills | G10: 22 | H10: MulMalwinaCofidis Women Team | I10: Cofidis Women Team | J10: 35 | K10: 2 | M10: ,,0:00
A11: 10 | B11: 40 | C11: +1:07 | D11: 186 | F11: Hills | G11: 23 | H11: RiedmannLindaLotto Intermarché Ladies | I11: Lotto Intermarché Ladies | J11: 30 | K11: 1 | M11: ,,0:00
A12: 11 | B12: 29 | C12: +0:50 | D12: 164 | F12: Hills | G12: 24 | H12: JansenElineVolkerWessels Cycling Team | I12: VolkerWessels Cycling Team | J12: 25 | M12: ,,0:00
A13: 12 | B13: 57 | C13: +2:16 | D13: 107 | F13: Classic | G13: 32 | H13: WilliamsLilyHuman Powered Health | I13: Human Powered Health | J13: 20 | M13: ,,0:00
A14: 13 | B14: 34 | C14: +0:57 | D14: 31 | F14: Hills | G14: 25 | H14: WłodarczykDominikaUAE Team L'IMAD | I14: UAE Team L'IMAD | J14: 15 | M14: ,,0:00
A15: 14 | B15: 25 | C15: +0:42 | D15: 13 | F15: Classic | G15: 20 | H15: GeryCéliaFDJ United - SUEZ | I15: FDJ United - SUEZ | J15: 10 | M15: ,,0:00
A16: 15 | B16: 75 | C16: +4:19 | D16: 94 | F16: Classic | G16: 22 | H16: CouzensMillieFenix-Premier Tech | I16: Fenix-Premier Tech | J16: 5 | M16: ,,0:00
A17: 16 | B17: 6 | C17: +0:20 | D17: 85 | F17: Hills | G17: 25 | H17: KerbaolCédrineEF Education-Oatly | I17: EF Education-Oatly | M17: ,,0:00
A18: 17 | B18: 23 | C18: +0:39 | D18: 151 | F18: Hills | G18: 28 | H18: OstolazaUsoaLaboral Kutxa - Fundación Euskadi | I18: Laboral Kutxa - Fundación Euskadi | M18: ,,0:00
A19: 18 | B19: 5 | C19: +0:20 | D19: 35 | F19: Classic | G19: 34 | H19: Longo BorghiniElisaUAE Team L'IMAD | I19: UAE Team L'IMAD | M19: ,,0:00
A20: 19 | B20: 13 | C20: +0:28 | D20: 32 | F20: Classic | G20: 23 | H20: BlasiPaulaUAE Team L'IMAD | I20: UAE Team L'IMAD | M20: ,,0:00
A21: 20 | B21: 58 | C21: +2:34 | D21: 73 | F21: Hills | G21: 27 | H21: BorghesiLetiziaAG Insurance - Soudal Team | I21: AG Insurance - Soudal Team | M21: ,,0:00
A22: 21 | B22: 14 | C22: +0:28 | D22: 34 | F22: Hills | G22: 42 | H22: GarcíaMaviUAE Team L'IMAD | I22: UAE Team L'IMAD | M22: ,,0:00
A23: 22 | B23: 56 | C23: +2:05 | D23: 84 | F23: Classic | G23: 33 | H23: FaulknerKristenEF Education-Oatly | I23: EF Education-Oatly | M23: ,,0:00
A24: 23 | B24: 30 | C24: +0:50 | D24: 6 | F24: Hills | G24: 24 | H24: Van DamSarahTeam Visma | Lease a Bike | I24: Team Visma | Lease a Bike | M24: ,,0:00
A25: 24 | B25: 42 | C25: +1:14 | D25: 24 | F25: Classic | G25: 30 | H25: KlöserRosa MariaCANYON//SRAM | I25: CANYON//SRAM | M25: ,,0:00
A26: 25 | B26: 67 | C26: +3:14 | D26: 36 | F26: Classic | G26: 29 | H26: PersicoSilviaUAE Team L'IMAD | I26: UAE Team L'IMAD | M26: ,,0:00
A27: 26 | B27: 19 | C27: +0:36 | D27: 104 | F27: TT | G27: 32 | H27: de JongThalitaHuman Powered Health | I27: Human Powered Health | M27: ,,0:00
A28: 27 | B28: 15 | C28: +0:28 | D28: 65 | F28: Climber | G28: 21 | H28: HolmgrenIsabellaLidl - Trek | I28: Lidl - Trek | M28: ,,0:00
... A139: 138 | B139: 138 | C139: +40:12 | D139: 184 | F139: Hills | G139: 23 | H139: HinojosaRominaLotto Intermarché Ladies | I139: Lotto Intermarché Ladies | M139: 24:5824:58
A140: 139 | B140: 139 | C140: +41:26 | D140: 182 | F140: Classic | G140: 21 | H140: BoelsDinaLotto Intermarché Ladies | I140: Lotto Intermarché Ladies | J140: -5 | L140: -60″ | M140: ,,24:58
A141: DNF | D141: 183 | F141: Sprint | G141: 22 | H141: EbrasElisabethLotto Intermarché Ladies | I141: Lotto Intermarché Ladies
A142: DNF | D142: 185 | F142: Hills | G142: 26 | H142: MeertMariekeLotto Intermarché Ladies | I142: Lotto Intermarché Ladies
A143: DNF | D143: 187 | F143: Sprint | G143: 22 | H143: VervloetSterreLotto Intermarché Ladies | I143: Lotto Intermarché Ladies
A144: DNF | D144: 165 | F144: TT | G144: 24 | H144: MolenaarLauraVolkerWessels Cycling Team | I144: VolkerWessels Cycling Team
A145: DNS | D145: 33 | F145: Hills | G145: 35 | H145: ChapmanBrodieUAE Team L'IMAD | I145: UAE Team L'IMAD
A146: DNS | D146: 97 | F146: TT | G146: 29 | H146: SchweinbergerChristinaFenix-Premier Tech | I146: Fenix-Premier Tech
A148: Rnk | B148: Prev | C148: ▼▲ | D148: BIB | E148: H2H | F148: Specialty | G148: Age | H148: Rider | I148: Team | J148: UCI | L148: Time | M148: Time won/lost
A149: 1 | B149: 1 | C149: - | D149: 47 | F149: Sprint | G149: 27 | H149: WiebesLorenaTeam SD Worx - Protime | I149: Team SD Worx - Protime | J149: 25 | K149: 20″ | L149: 7:10:597:10:59 | M149: ..
A150: 2 | B150: 2 | C150: - | D150: 71 | F150: Classic | G150: 30 | H150: Le Court-PienaarKimAG Insurance - Soudal Team | I150: AG Insurance - Soudal Team | K150: 6″ | L150: 0:140:14 | M150: ..
A151: 3 | B151: 3 | C151: - | D151: 11 | F151: Classic | G151: 29 | H151: VolleringDemiFDJ United - SUEZ | I151: FDJ United - SUEZ | K151: 4″ | L151: 0:160:16 | M151: ..
...

Sheet Tabelle9
A1: Rnk | B1: GC | C1: Timelag | D1: BIB | E1: H2H | F1: Specialty | G1: Age | H1: Rider | I1: Team | J1: UCI | K1: Pnt | M1: Time
A2: 1 | B2: 1 | C2: +0:00 | D2: 174 | F2: Hills | G2: 27 | H2: HaugsetSigrid Ytterhus Uno-X Mobility | I2: Uno-X Mobility | J2: 210 | K2: 50 | L2: 16″ | M2: 4:05:594:05:59
A3: 2 | B3: 30 | C3: +2:54 | D3: 45 | F3: Classic | G3: 30 | H3: KopeckyLotte Team SD Worx - Protime | I3: Team SD Worx - Protime | J3: 150 | K3: 30 | L3: 10″ | M3: 1:241:24
A4: 3 | B4: 5 | C4: +2:10 | D4: 7 | F4: Classic | G4: 39 | H4: VosMarianneTeam Visma | Lease a Bike | I4: Team Visma | Lease a Bike | J4: 110 | K4: 18 | L4: 4″ | M4: 2:482:48
A5: 4 | B5: 23 | C5: +2:29 | D5: 151 | F5: Hills | G5: 28 | H5: OstolazaUsoaLaboral Kutxa - Fundación Euskadi | I5: Laboral Kutxa - Fundación Euskadi | J5: 90 | K5: 13 | M5: ,,2:48
A6: 5 | B6: 2 | C6: +2:02 | D6: 71 | F6: Classic | G6: 30 | H6: Le Court-PienaarKimAG Insurance - Soudal Team | I6: AG Insurance - Soudal Team | J6: 70 | K6: 10 | L6: 2″ | M6: ,,2:48
A7: 6 | B7: 4 | C7: +2:10 | D7: 86 | F7: Classic | G7: 25 | H7: RüeggNoemiEF Education-Oatly | I7: EF Education-Oatly | J7: 55 | K7: 7 | M7: ,,2:48
A8: 7 | B8: 25 | C8: +2:32 | D8: 13 | F8: Classic | G8: 20 | H8: GeryCéliaFDJ United - SUEZ | I8: FDJ United - SUEZ | J8: 45 | K8: 4 | M8: ,,2:48
A9: 8 | B9: 6 | C9: +2:10 | D9: 85 | F9: Hills | G9: 25 | H9: MulMalwinaCofidis Women Team | I9: EF Education-Oatly | J9: 40 | K9: 3 | M9: ,,2:48
A10: 9 | B10: 22 | C10: +2:29 | D10: 141 | F10: Hills | G10: 22 | H10: KerbaolCédrineEF Education-Oatly | I10: Cofidis Women Team | J10: 35 | K10: 2 | M10: ,,2:48
A11: 10 | B11: 20 | C11: +2:26 | D11: 111 | F11: Hills | G11: 27 | H11: Trinca ColonelMonicaLiv AlUla Jayco | I11: Liv AlUla Jayco | J11: 30 | K11: 1 | M11: ,,2:48
A12: 11 | B12: 27 | C12: +2:47 | D12: 31 | F12: Hills | G12: 25 | H12: WłodarczykDominikaUAE Team L'IMAD | I12: UAE Team L'IMAD | J12: 25 | M12: ,,2:48
A13: 12 | B13: 37 | C13: +4:56 | D13: 66 | F13: TT | G13: 31 | H13: MarkusRiejanneLidl - Trek | I13: Lidl - Trek | J13: 20 | M13: ,,2:48
A14: 13 | B14: 19 | C14: +2:26 | D14: 104 | F14: TT | G14: 32 | H14: de JongThalitaHuman Powered Health | I14: Human Powered Health | J14: 15 | M14: ,,2:48
A15: 14 | B15: 13 | C15: +2:18 | D15: 32 | F15: Hills | G15: 23 | H15: BlasiPaulaUAE Team L'IMAD | I15: UAE Team L'IMAD | J15: 10 | M15: ,,2:48
A16: 15 | B16: 9 | C16: +2:10 | D16: 91 | F16: Classic | G16: 24 | H16: PietersePuckFenix-Premier Tech | I16: Fenix-Premier Tech | J16: 5 | M16: ,,2:48
A17: 16 | B17: 8 | C17: +2:10 | D17: 21 | F17: Classic | G17: 31 | H17: NiewiadomaKasiaCANYON//SRAM | I17: CANYON//SRAM | M17: ,,2:48
A18: 17 | B18: 28 | C18: +2:47 | D18: 193 | F18: Hills | G18: 28 | H18: AsencioLauraMa Petite Entreprise | I18: Ma Petite Entreprise | M18: ,,2:48
A19: 18 | B19: 16 | C19: +2:18 | D19: 25 | F19: GC | G19: 23 | H19: NiedermaierAntoniaCANYON//SRAM | I19: CANYON//SRAM | M19: ,,2:48
A20: 19 | B20: 14 | C20: +2:18 | D20: 34 | F20: Hills | G20: 42 | H20: Longo BorghiniElisaUAE Team L'IMAD | I20: UAE Team L'IMAD | M20: ,,2:48
A21: 20 | B21: 7 | C21: +2:10 | D21: 35 | F21: Classic | G21: 34 | H21: GarcíaMaviUAE Team L'IMAD | I21: UAE Team L'IMAD | M21: ,,2:48
A22: 21 | B22: 32 | C22: +3:15 | D22: 46 | F22: GC | G22: 22 | H22: VinkeNienkeTeam SD Worx - Protime | I22: Team SD Worx - Protime | M22: ,,2:48
A23: 22 | B23: 21 | C23: +2:26 | D23: 131 | F23: Hills | G23: 29 | H23: MorierÉmilieSt Michel - Preference Home - Auber93 | I23: St Michel - Preference Home - Auber93 | M23: ,,2:48
A24: 23 | B24: 3 | C24: +2:06 | D24: 11 | F24: Classic | G24: 29 | H24: VolleringDemiFDJ United - SUEZ | I24: FDJ United - SUEZ | M24: ,,2:48
A25: 24 | B25: 12 | C25: +2:15 | D25: 64 | F25: GC | G25: 25 | H25: Fisher-BlackNiamhLidl - Trek | I25: Lidl - Trek | M25: ,,2:48
A26: 25 | B26: 33 | C26: +3:15 | D26: 102 | F26: Hills | G26: 28 | H26: BuijsmanNinaHuman Powered Health | I26: Human Powered Health | M26: ,,2:48
A27: 26 | B27: 39 | C27: +6:20 | D27: 147 | F27: Hills | G27: 29 | H27: NoskováNikolaCofidis Women Team | I27: Cofidis Women Team | M27: ,,2:48
A28: 27 | B28: 15 | C28: +2:18 | D28: 65 | F28: Climber | G28: 21 | H28: HolmgrenIsabellaLidl - Trek | I28: Lidl - Trek | M28: ,,2:48
... A139: 138 | B139: 137 | C139: +59:30 | D139: 146 | F139: TT | G139: 26 | H139: LudwigHannahCofidis Women Team | I139: Cofidis Women Team | M139: ,,25:51
A140: DNF | D140: 182 | F140: Classic | G140: 21 | H140: BoelsDinaLotto Intermarché Ladies | I140: Lotto Intermarché Ladies
A142: Rnk | B142: Prev | C142: ▼▲ | D142: BIB | E142: H2H | F142: Specialty | G142: Age | H142: Rider | I142: Team | J142: UCI | L142: Time | M142: Time won/lost
A143: 1 | B143: 46 | C143: ▲45 | D143: 174 | F143: Hills | G143: 27 | H143: HaugsetSigrid YtterhusUno-X Mobility | I143: Uno-X Mobility | J143: 25 | K143: 16″ | L143: 11:17:56 11:17:56 | M143: ..
A144: 2 | B144: 2 | C144: - | D144: 71 | F144: Classic | G144: 30 | H144: Le Court-PienaarKimAG Insurance - Soudal Team | I144: AG Insurance - Soudal Team | K144: 8″ | L144: 2:022:02 | M144: ..
A145: 3 | B145: 3 | C145: - | D145: 11 | F145: Classic | G145: 29 | H145: VolleringDemiFDJ United - SUEZ | I145: FDJ United - SUEZ | K145: 4″ | L145: 2:062:06 | M145: ..
A146: 4 | B146: 4 | C146: - | D146: 86 | F146: Classic | G146: 25 | H146: RüeggNoemiEF Education-Oatly | I146: EF Education-Oatly | L146: 2:102:10 | M146: ..
A147: 5 | B147: 11 | C147: ▲6 | D147: 7 | F147: Classic | G147: 39 | H147: VosMarianneTeam Visma | Lease a Bike | I147: Team Visma | Lease a Bike | K147: 8″ | L147: ,,2:10 | M147: ..
A148: 6 | B148: 6 | C148: - | D148: 85 | F148: Hills | G148: 25 | H148: Longo BorghiniElisaUAE Team L'IMAD | I148: EF Education-Oatly | L148: ,,2:10 | M148: ..
A149: 7 | B149: 5 | C149: ▼2 | D149: 35 | F149: Classic | G149: 34 | H149: KerbaolCédrineEF Education-Oatly | I149: UAE Team L'IMAD | L149: ,,2:10 | M149: ..
A150: 8 | B150: 7 | C150: ▼1 | D150: 21 | F150: Classic | G150: 31 | H150: NiewiadomaKasiaCANYON//SRAM | I150: CANYON//SRAM | L150: ,,2:10 | M150: ..
A151: 9 | B151: 8 | C151: ▼1 | D151: 91 | F151: Classic | G151: 24 | H151: PietersePuckFenix-Premier Tech | I151: Fenix-Premier Tech | L151: ,,2:10 | M151: ..
...

Sheet Tabelle10
A1: Rnk | B1: GC | C1: Timelag | D1: BIB | E1: H2H | F1: Specialty | G1: Age | H1: Rider | I1: Team | J1: UCI | K1: Pnt | M1: Time | N1: Avg
A2: 1 | B2: 1 | C2: +0:00 | D2: 51 | F2: TT | G2: 34 | H2: ReusserMarlenMovistar Team | I2: Movistar Team | J2: 210 | K2: 50 | M2: 27.30,09 | N2: 45816
A3: 2 | B3: 65 | C3: +17:53 | D3: 5 | F3: TT | G3: 25 | H3: NooijenLiekeTeam Visma | Lease a Bike | I3: Team Visma | Lease a Bike | J3: 150 | K3: 30 | M3: 0.04,08 | N3: 45703
A4: 3 | B4: 2 | C4: +0:14 | D4: 11 | F4: Classic | G4: 29 | H4: VolleringDemiFDJ United - SUEZ | I4: FDJ United - SUEZ | J4: 110 | K4: 18 | M4: 0.17,92 | N4: 45323
A5: 4 | B5: 34 | C5: +4:32 | D5: 22 | F5: TT | G5: 21 | H5: BäckstedtZoeCANYON//SRAM | I5: CANYON//SRAM | J5: 90 | K5: 13 | M5: 0.19,91 | N5: 45269
A6: 5 | B6: 64 | C6: +17:45 | D6: 42 | F6: Hills | G6: 26 | H6: BredewoldMischaTeam SD Worx - Protime | I6: Team SD Worx - Protime | J6: 70 | K6: 10 | M6: 0.45,42 | N6: 44588
A7: 6 | B7: 38 | C7: +6:14 | D7: 84 | F7: Classic | G7: 33 | H7: FaulknerKristenEF Education-Oatly | I7: EF Education-Oatly | J7: 55 | K7: 7 | M7: 0.54,43 | N7: 44353
A8: 7 | B8: 3 | C8: +0:54 | D8: 85 | F8: Hills | G8: 25 | H8: KerbaolCédrineEF Education-Oatly | I8: EF Education-Oatly | J8: 45 | K8: 4 | M8: 0.54,6 | N8: 44348
A9: 8 | B9: 91 | C9: +27:00 | D9: 93 | F9: Hills | G9: 33 | H9: MarkusRiejanneLidl - Trek | I9: Fenix-Premier Tech | J9: 40 | K9: 3 | M9: 0.55,01 | N9: 44338
A10: 9 | B10: 28 | C10: +3:47 | D10: 66 | F10: TT | G10: 31 | H10: ClaesLotteFenix-Premier Tech | I10: Lidl - Trek | J10: 35 | K10: 2 | M10: 1.00,95 | N10: 44184
A11: 10 | B11: 5 | C11: +1:03 | D11: 35 | F11: Classic | G11: 34 | H11: Longo BorghiniElisaUAE Team L'IMAD | I11: UAE Team L'IMAD | J11: 30 | K11: 1 | M11: 1.03,23 | N11: 44125
A12: 11 | B12: 7 | C12: +1:12 | D12: 32 | F12: Hills | G12: 23 | H12: BlasiPaulaUAE Team L'IMAD | I12: UAE Team L'IMAD | J12: 25 | M12: 1.04,7 | N12: 44087
A13: 12 | B13: 79 | C13: +22:38 | D13: 94 | F13: Classic | G13: 22 | H13: CouzensMillieFenix-Premier Tech | I13: Fenix-Premier Tech | J13: 20 | M13: 1.08,84 | N13: 43981
A14: 13 | B14: 6 | C14: +1:09 | D14: 21 | F14: Classic | G14: 31 | H14: NiewiadomaKasiaCANYON//SRAM | I14: CANYON//SRAM | J14: 15 | M14: 1.08,93 | N14: 43979
A15: 14 | B15: 8 | C15: +1:17 | D15: 41 | F15: Classic | G15: 36 | H15: van der BreggenAnnaTeam SD Worx - Protime | I15: Team SD Worx - Protime | J15: 10 | M15: 1.09,89 | N15: 43954
A16: 15 | B16: 10 | C16: +1:47 | D16: 3 | F16: Hills | G16: 32 | H16: de VriesFemkeTeam Visma | Lease a Bike | I16: Team Visma | Lease a Bike | J16: 5 | M16: 1.17,01 | N16: 43773
A17: 16 | B17: 119 | C17: +42:13 | D17: 181 | F17: TT | G17: 30 | H17: TasSandrineLotto Intermarché Ladies | I17: Lotto Intermarché Ladies | M17: 1.19,3 | N17: 43715
A18: 17 | B18: 129 | C18: +45:27 | D18: 196 | F18: TT | G18: 26 | H18: Le MouëlCéliaMa Petite Entreprise | I18: Ma Petite Entreprise | M18: 1.20,26 | N18: 43691
A19: 18 | B19: 11 | C19: +1:59 | D19: 31 | F19: Hills | G19: 25 | H19: WłodarczykDominikaUAE Team L'IMAD | I19: UAE Team L'IMAD | M19: 1.22,43 | N19: 43636
A20: 19 | B20: 17 | C20: +2:30 | D20: 46 | F20: GC | G20: 22 | H20: KochFranziskaFDJ United - SUEZ | I20: Team SD Worx - Protime | M20: 1.25,28 | N20: 43564
A21: 20 | B21: 69 | C21: +20:22 | D21: 14 | F21: Classic | G21: 26 | H21: VinkeNienkeTeam SD Worx - Protime | I21: FDJ United - SUEZ | M21: 1.27,84 | N21: 43500
A22: 21 | B22: 104 | C22: +34:16 | D22: 4 | F22: TT | G22: 23 | H22: HengeveldDaniekTeam Visma | Lease a Bike | I22: Team Visma | Lease a Bike | M22: 1.29,1 | N22: 43469
A23: 22 | B23: 13 | C23: +2:11 | D23: 171 | F23: Hills | G23: 31 | H23: AalerudKatrineUno-X Mobility | I23: Uno-X Mobility | M23: 1.34,59 | N23: 43332
A24: 23 | B24: 95 | C24: +30:27 | D24: 103 | F24: Hills | G24: 23 | H24: CipressiCarlottaHuman Powered Health | I24: Human Powered Health | M24: 1.34,99 | N24: 43322
A25: 24 | B25: 9 | C25: +1:43 | D25: 25 | F25: GC | G25: 23 | H25: NiedermaierAntoniaCANYON//SRAM | I25: CANYON//SRAM | M25: 1.35,66 | N25: 43305
A26: 25 | B26: 73 | C26: +21:04 | D26: 107 | F26: Classic | G26: 32 | H26: WilliamsLilyHuman Powered Health | I26: Human Powered Health | M26: 1.37,3 | N26: 43265
A27: 26 | B27: 53 | C27: +9:27 | D27: 6 | F27: Hills | G27: 24 | H27: Van DamSarahTeam Visma | Lease a Bike | I27: Team Visma | Lease a Bike | M27: 1.44,41 | N27: 43089
A28: 27 | B28: 66 | C28: +18:56 | D28: 47 | F28: Sprint | G28: 27 | H28: WiebesLorenaTeam SD Worx - Protime | I28: Team SD Worx - Protime | M28: 1.45,08 | N28: 43073
... A139: 138 | B139: 138 | C139: +1:03:37 | D139: 146 | F139: TT | G139: 26 | H139: LudwigHannahCofidis Women Team | I139: Cofidis Women Team | M139: 6.17,78 | N139: 37280
A141: Rnk | B141: Prev | C141: ▼▲ | D141: BIB | E141: H2H | F141: Specialty | G141: Age | H141: Rider | I141: Team | J141: UCI | L141: Time | M141: Time won/lost
A142: 1 | B142: 11 | C142: ▲10 | D142: 51 | F142: TT | G142: 34 | H142: ReusserMarlenMovistar Team | I142: Movistar Team | J142: 25 | L142: 11:47:36 11:47:36 | M142: ..
A143: 2 | B143: 3 | C143: ▲1 | D143: 11 | F143: Classic | G143: 29 | H143: VolleringDemiFDJ United - SUEZ | I143: FDJ United - SUEZ | K143: 4″ | L143: 0:140:14 | M143: ..
A144: 3 | B144: 6 | C144: ▲3 | D144: 85 | F144: Hills | G144: 25 | H144: KerbaolCédrineEF Education-Oatly | I144: EF Education-Oatly | L144: 0:540:54 | M144: ..
A145: 4 | B145: 1 | C145: ▼3 | D145: 174 | F145: Hills | G145: 27 | H145: HaugsetSigrid YtterhusUno-X Mobility | I145: Uno-X Mobility | K145: 16″ | L145: 0:560:56 | M145: ..
A146: 5 | B146: 7 | C146: ▲2 | D146: 35 | F146: Classic | G146: 34 | H146: Longo BorghiniElisaUAE Team L'IMAD | I146: UAE Team L'IMAD | L146: 1:031:03 | M146: ..
A147: 6 | B147: 8 | C147: ▲2 | D147: 21 | F147: Classic | G147: 31 | H147: NiewiadomaKasiaCANYON//SRAM | I147: CANYON//SRAM | L147: 1:091:09 | M147: ..
A148: 7 | B148: 13 | C148: ▲6 | D148: 32 | F148: Hills | G148: 23 | H148: BlasiPaulaUAE Team L'IMAD | I148: UAE Team L'IMAD | L148: 1:121:12 | M148: ..
A149: 8 | B149: 18 | C149: ▲10 | D149: 41 | F149: Classic | G149: 36 | H149: van der BreggenAnnaTeam SD Worx - Protime | I149: Team SD Worx - Protime | L149: 1:171:17 | M149: ..
A150: 9 | B150: 16 | C150: ▲7 | D150: 25 | F150: GC | G150: 23 | H150: NiedermaierAntoniaCANYON//SRAM | I150: CANYON//SRAM | L150: 1:431:43 | M150: ..
A151: 10 | B151: 26 | C151: ▲16 | D151: 3 | F151: Hills | G151: 32 | H151: de VriesFemkeTeam Visma | Lease a Bike | I151: Team Visma | Lease a Bike | L151: 1:471:47 | M151: ..
...

Sheet Tabelle11
A1: Rnk | B1: GC | C1: Timelag | D1: BIB | E1: H2H | F1: Specialty | G1: Age | H1: Rider | I1: Team | J1: UCI | K1: Pnt | M1: Time
A2: 1 | B2: 2 | C2: +0:12 | D2: 11 | F2: Classic | G2: 29 | H2: VolleringDemiFDJ United - SUEZ | I2: FDJ United - SUEZ | J2: 210 | K2: 50 | L2: 14″ | M2: 3:53:543:53:54
A3: 2 | B3: 1 | C3: +0:00 | D3: 51 | F3: TT | G3: 34 | H3: ReusserMarlenMovistar Team | I3: Movistar Team | J3: 150 | K3: 30 | L3: 12″ | M3: ,,0:00
A4: 3 | B4: 3 | C4: +1:17 | D4: 21 | F4: Classic | G4: 31 | H4: NiewiadomaKasiaCANYON//SRAM | I4: CANYON//SRAM | J4: 110 | K4: 18 | L4: 4″ | M4: ,,0:00
A5: 4 | B5: 5 | C5: +2:54 | D5: 31 | F5: Hills | G5: 25 | H5: WłodarczykDominikaUAE Team L'IMAD | I5: UAE Team L'IMAD | J5: 90 | K5: 13 | L5: 2″ | M5: 0:450:45
A6: 5 | B6: 7 | C6: +3:05 | D6: 65 | F6: Climber | G6: 21 | H6: HolmgrenIsabellaLidl - Trek | I6: Lidl - Trek | J6: 70 | K6: 10 | M6: ,,0:45
A7: 6 | B7: 4 | C7: +2:40 | D7: 25 | F7: GC | G7: 23 | H7: NiedermaierAntoniaCANYON//SRAM | I7: CANYON//SRAM | J7: 55 | K7: 7 | M7: ,,0:45
A8: 7 | B8: 11 | C8: +3:54 | D8: 46 | F8: GC | G8: 22 | H8: VinkeNienkeTeam SD Worx - Protime | I8: Team SD Worx - Protime | J8: 45 | K8: 4 | M8: 1:121:12
A9: 8 | B9: 8 | C9: +3:11 | D9: 3 | F9: Hills | G9: 32 | H9: de VriesFemkeTeam Visma | Lease a Bike | I9: Team Visma | Lease a Bike | J9: 40 | K9: 3 | M9: ,,1:12
A10: 9 | B10: 14 | C10: +4:28 | D10: 104 | F10: TT | G10: 32 | H10: Fisher-BlackNiamh Lidl - Trek | I10: Human Powered Health | J10: 35 | K10: 2 | M10: ,,1:12
A11: 10 | B11: 15 | C11: +4:34 | D11: 64 | F11: GC | G11: 25 | H11: de JongThalitaHuman Powered Health | I11: Lidl - Trek | J11: 30 | K11: 1 | M11: 1:151:15
A12: 11 | B12: 18 | C12: +5:33 | D12: 91 | F12: Classic | G12: 24 | H12: PietersePuckFenix-Premier Tech | I12: Fenix-Premier Tech | J12: 25 | M12: 1:431:43
A13: 12 | B13: 13 | C13: +4:10 | D13: 71 | F13: Classic | G13: 30 | H13: Le Court-PienaarKimAG Insurance - Soudal Team | I13: AG Insurance - Soudal Team | J13: 20 | M13: ,,1:43
A14: 13 | B14: 16 | C14: +4:47 | D14: 12 | F14: GC | G14: 27 | H14: BerthetJulietteFDJ United - SUEZ | I14: FDJ United - SUEZ | J14: 15 | M14: ,,1:43
A15: 14 | B15: 6 | C15: +2:58 | D15: 35 | F15: Classic | G15: 34 | H15: Longo BorghiniElisaUAE Team L'IMAD | I15: UAE Team L'IMAD | J15: 10 | M15: ,,1:43
A16: 15 | B16: 10 | C16: +3:51 | D16: 32 | F16: Hills | G16: 23 | H16: BlasiPaulaUAE Team L'IMAD | I16: UAE Team L'IMAD | J16: 5 | M16: 2:272:27
A17: 16 | B17: 23 | C17: +9:10 | D17: 67 | F17: Classic | G17: 38 | H17: SprattAmandaLidl - Trek | I17: Lidl - Trek | M17: ,,2:27
A18: 17 | B18: 9 | C18: +3:41 | D18: 85 | F18: Hills | G18: 25 | H18: KerbaolCédrineEF Education-Oatly | I18: EF Education-Oatly | M18: 2:352:35
A19: 18 | B19: 12 | C19: +4:04 | D19: 41 | F19: Classic | G19: 36 | H19: van der BreggenAnnaTeam SD Worx - Protime | I19: Team SD Worx - Protime | M19: ,,2:35
A20: 19 | B20: 17 | C20: +5:00 | D20: 1 | F20: Classic | G20: 34 | H20: Ferrand-PrévotPaulineTeam Visma | Lease a Bike | I20: Team Visma | Lease a Bike | J20: -15 | M20: ,,2:35
A21: 20 | B21: 19 | C21: +7:52 | D21: 76 | F21: Hills | G21: 30 | H21: GhekiereJustineAG Insurance - Soudal Team | I21: AG Insurance - Soudal Team | M21: 2:392:39
A22: 21 | B22: 86 | C22: +48:59 | D22: 196 | F22: TT | G22: 26 | H22: Le MouëlCéliaMa Petite Entreprise | I22: Ma Petite Entreprise | M22: 3:203:20
A23: 22 | B23: 30 | C23: +11:42 | D23: 81 | F23: Classic | G23: 24 | H23: VallieresMagdeleineEF Education-Oatly | I23: EF Education-Oatly | M23: 3:273:27
A24: 23 | B24: 31 | C24: +12:04 | D24: 37 | F24: Hills | G24: 24 | H24: SquibanMaevaUAE Team L'IMAD | I24: UAE Team L'IMAD | M24: 5:365:36
A25: 24 | B25: 21 | C25: +8:43 | D25: 34 | F25: Hills | G25: 42 | H25: GarcíaMaviUAE Team L'IMAD | I25: UAE Team L'IMAD | M25: ,,5:36
A26: 25 | B26: 25 | C26: +9:29 | D26: 131 | F26: Hills | G26: 29 | H26: MorierÉmilieSt Michel - Preference Home - Auber93 | I26: St Michel - Preference Home - Auber93 | M26: 6:156:15
A27: 26 | B27: 26 | C27: +9:53 | D27: 102 | F27: Hills | G27: 28 | H27: BuijsmanNinaHuman Powered Health | I27: Human Powered Health | M27: ,,6:15
A28: 27 | B28: 77 | C28: +44:25 | D28: 197 | F28: Hills | G28: 24 | H28: MahéOcéaneMa Petite Entreprise | I28: Ma Petite Entreprise | M28: ,,6:15
A29: 28 | B29: 45 | C29: +23:28 | D29: 201 | F29: Hills | G29: 27 | H29: PerekitkoKarolinaMayenne Monbana My Pie | I29: Mayenne Monbana My Pie | M29: ,,6:15
A30: 29 | B30: 20 | C30: +8:38 | D30: 171 | F30: Hills | G30: 31 | H30: AalerudKatrineUno-X Mobility | I30: Uno-X Mobility | M30: ,,6:15
A31: 30 | B31: 33 | C31: +13:17 | D31: 113 | F31: TT | G31: 25 | H31: GontovaNadiaLiv AlUla Jayco | I31: Liv AlUla Jayco | M31: ,,6:15
A32: 31 | B32: 29 | C32: +11:40 | D32: 193 | F32: Hills | G32: 28 | H32: AsencioLauraMa Petite Entreprise | I32: Ma Petite Entreprise | M32: ,,6:15
... A136: 135 | B136: 129 | C136: +1:15:22 | D136: 135 | F136: Classic | G136: 37 | H136: JacksonAlisonSt Michel - Preference Home - Auber93 | I136: St Michel - Preference Home - Auber93 | M136: ,,30:08
A137: DNF | D137: 134 | F137: Hills | G137: 26 | H137: GrangierIndiaSt Michel - Preference Home - Auber93 | I137: St Michel - Preference Home - Auber93
A138: DNS | D138: 172 | F138: Classic | G138: 30 | H138: BeekhuisTeuntjeUno-X Mobility | I138: Uno-X Mobility
A139: DNS | D139: 146 | F139: TT | G139: 26 | H139: LudwigHannahCofidis Women Team | I139: Cofidis Women Team
A141: Rnk | B141: Prev | C141: ▼▲ | D141: BIB | E141: H2H | F141: Specialty | G141: Age | H141: Rider | I141: Team | J141: UCI | L141: Time | M141: Time won/lost
A142: 1 | B142: 1 | C142: - | D142: 51 | F142: TT | G142: 34 | H142: ReusserMarlenMovistar Team | I142: Movistar Team | J142: 25 | K142: 12″ | L142: 15:41:18 15:41:18 | M142: ..
A143: 2 | B143: 2 | C143: - | D143: 11 | F143: Classic | G143: 29 | H143: VolleringDemiFDJ United - SUEZ | I143: FDJ United - SUEZ | K143: 18″ | L143: 0:120:12 | M143: ..
A144: 3 | B144: 6 | C144: ▲3 | D144: 21 | F144: Classic | G144: 31 | H144: NiewiadomaKasiaCANYON//SRAM | I144: CANYON//SRAM | K144: 4″ | L144: 1:171:17 | M144: ..
...
