Workbook

Sheet Auswertung Gesamt
A1: Name | B1: Summe
A2: Conni K | B2: =SUM('Auswertung Stage'!B4:AA4) -> 1423
A3: Cindy | B3: =SUM('Auswertung Stage'!B5:AA5) -> 1027
A4: Sebbo | B4: =SUM('Auswertung Stage'!B6:AA6) -> 943
A5: Lanci | B5: =SUM('Auswertung Stage'!B7:AA7) -> 1095
A6: Till | B6: =SUM('Auswertung Stage'!B8:AA8) -> 1066
A7: Richard NB | B7: =SUM('Auswertung Stage'!B9:AA9) -> 1105
A8: Jakob | B8: =SUM('Auswertung Stage'!B10:AA10) -> 775
A9: Lea | B9: =SUM('Auswertung Stage'!B11:AA11) -> 1002
A10: Chris | B10: =SUM('Auswertung Stage'!B12:AA12) -> 1501
A11: Jule | B11: =SUM('Auswertung Stage'!B13:AA13) -> 1066
A12: Konsti | B12: =SUM('Auswertung Stage'!B14:AA14) -> 1201
A13: Nora | B13: =SUM('Auswertung Stage'!B15:AA15) -> 1521
... A18: Chrysli | B18: =SUM('Auswertung Stage'!B20:AA20) -> 0

Sheet Auswertung Stage
B1: S 01 | C1: S 02 | D1: S 03 | E1: S 04 | F1: S 05 | G1: S 06 | H1: S 07 | I1: S 08 | J1: S 09 | K1: S 10 | L1: S 11 | M1: S 12 | N1: S 13 | O1: S 14 | P1: S 15 | Q1: S 16 | R1: S 17 | S1: S 18 | T1: S 19 | U1: S 20 | V1: S 21 | W1: S 22 GC | X1: S 23 Mountain | Y1: S 24 Sprint | Z1: S 25 Youth | AA1: S 26 TeamRank
A2: Jakob | B2: =SUMIF(Spieler_Teams!$A:$A,$A2,Spieler_Teams!C:C) -> 71 | C2: =SUMIF(Spieler_Teams!$A:$A,$A2,Spieler_Teams!D:D) -> 49 | D2: =SUMIF(Spieler_Teams!$A:$A,$A2,Spieler_Teams!E:E) -> 70 | E2: =SUMIF(Spieler_Teams!$A:$A,$A2,Spieler_Teams!F:F) -> 0 | F2: =SUMIF(Spieler_Teams!$A:$A,$A2,Spieler_Teams!G:G) -> 15 | G2: =SUMIF(Spieler_Teams!$A:$A,$A2,Spieler_Teams!H:H) -> 72 | H2: =SUMIF(Spieler_Teams!$A:$A,$A2,Spieler_Teams!I:I) -> 30 | I2: =SUMIF(Spieler_Teams!$A:$A,$A2,Spieler_Teams!J:J) -> 31 | J2: =SUMIF(Spieler_Teams!$A:$A,$A2,Spieler_Teams!K:K) -> 35 | K2: =SUMIF(Spieler_Teams!$A:$A,$A2,Spieler_Teams!L:L) -> 69 | L2: =SUMIF(Spieler_Teams!$A:$A,$A2,Spieler_Teams!M:M) -> 8 | M2: =SUMIF(Spieler_Teams!$A:$A,$A2,Spieler_Teams!N:N) -> 34 | N2: =SUMIF(Spieler_Teams!$A:$A,$A2,Spieler_Teams!O:O) -> 7 | O2: =SUMIF(Spieler_Teams!$A:$A,$A2,Spieler_Teams!P:P) -> 71 | P2: =SUMIF(Spieler_Teams!$A:$A,$A2,Spieler_Teams!Q:Q) -> 54 | Q2: =SUMIF(Spieler_Teams!$A:$A,$A2,Spieler_Teams!R:R) -> 39 | R2: =SUMIF(Spieler_Teams!$A:$A,$A2,Spieler_Teams!S:S) -> 10 | S2: =SUMIF(Spieler_Teams!$A:$A,$A2,Spieler_Teams!T:T) -> 12 | T2: =SUMIF(Spieler_Teams!$A:$A,$A2,Spieler_Teams!U:U) -> 38 | U2: =SUMIF(Spieler_Teams!$A:$A,$A2,Spieler_Teams!V:V) -> 29 | V2: =SUMIF(Spieler_Teams!$A:$A,$A2,Spieler_Teams!W:W) -> 28 | W2: =SUMIF(Spieler_Teams!$A:$A,$A2,Spieler_Teams!X:X) -> 180 | X2: =SUMIF(Spieler_Teams!$A:$A,$A2,Spieler_Teams!Y:Y) -> 24 | Y2: =SUMIF(Spieler_Teams!$A:$A,$A2,Spieler_Teams!Z:Z) -> 8 | Z2: =SUMIF(Spieler_Teams!$A:$A,$A2,Spieler_Teams!AA:AA) -> 10 | AA2: =SUMIF(Spieler_Teams!$A:$A,$A2,Spieler_Teams!AB:AB) -> 25
A3: Cindy | B3: =SUMIF(Spieler_Teams!A:A,A3,Spieler_Teams!C:C) -> 67 | C3: =SUMIF(Spieler_Teams!$A:$A,$A3,Spieler_Teams!D:D) -> 78 | D3: =SUMIF(Spieler_Teams!$A:$A,$A3,Spieler_Teams!E:E) -> 73 | E3: =SUMIF(Spieler_Teams!$A:$A,$A3,Spieler_Teams!F:F) -> 0 | F3: =SUMIF(Spieler_Teams!$A:$A,$A3,Spieler_Teams!G:G) -> 0 | G3: =SUMIF(Spieler_Teams!$A:$A,$A3,Spieler_Teams!H:H) -> 79 | H3: =SUMIF(Spieler_Teams!$A:$A,$A3,Spieler_Teams!I:I) -> 7 | I3: =SUMIF(Spieler_Teams!$A:$A,$A3,Spieler_Teams!J:J) -> 8 | J3: =SUMIF(Spieler_Teams!$A:$A,$A3,Spieler_Teams!K:K) -> 55 | K3: =SUMIF(Spieler_Teams!$A:$A,$A3,Spieler_Teams!L:L) -> 68 | L3: =SUMIF(Spieler_Teams!$A:$A,$A3,Spieler_Teams!M:M) -> 5 | M3: =SUMIF(Spieler_Teams!$A:$A,$A3,Spieler_Teams!N:N) -> 9 | N3: =SUMIF(Spieler_Teams!$A:$A,$A3,Spieler_Teams!O:O) -> 20 | O3: =SUMIF(Spieler_Teams!$A:$A,$A3,Spieler_Teams!P:P) -> 79 | P3: =SUMIF(Spieler_Teams!$A:$A,$A3,Spieler_Teams!Q:Q) -> 57 | Q3: =SUMIF(Spieler_Teams!$A:$A,$A3,Spieler_Teams!R:R) -> 54 | R3: =SUMIF(Spieler_Teams!$A:$A,$A3,Spieler_Teams!S:S) -> 12 | S3: =SUMIF(Spieler_Teams!$A:$A,$A3,Spieler_Teams!T:T) -> 16 | T3: =SUMIF(Spieler_Teams!$A:$A,$A3,Spieler_Teams!U:U) -> 47 | U3: =SUMIF(Spieler_Teams!$A:$A,$A3,Spieler_Teams!V:V) -> 34 | V3: =SUMIF(Spieler_Teams!$A:$A,$A3,Spieler_Teams!W:W) -> 30 | W3: =SUMIF(Spieler_Teams!$A:$A,$A3,Spieler_Teams!X:X) -> 230 | X3: =SUMIF(Spieler_Teams!$A:$A,$A3,Spieler_Teams!Y:Y) -> 34 | Y3: =SUMIF(Spieler_Teams!$A:$A,$A3,Spieler_Teams!Z:Z) -> 12 | Z3: =SUMIF(Spieler_Teams!$A:$A,$A3,Spieler_Teams!AA:AA) -> 25 | AA3: =SUMIF(Spieler_Teams!$A:$A,$A3,Spieler_Teams!AB:AB) -> 0
A4: Conni K | B4: =SUMIF(Spieler_Teams!A:A,A4,Spieler_Teams!C:C) -> 66 | C4: =SUMIF(Spieler_Teams!$A:$A,$A4,Spieler_Teams!D:D) -> 62 | D4: =SUMIF(Spieler_Teams!$A:$A,$A4,Spieler_Teams!E:E) -> 90 | E4: =SUMIF(Spieler_Teams!$A:$A,$A4,Spieler_Teams!F:F) -> 29 | F4: =SUMIF(Spieler_Teams!$A:$A,$A4,Spieler_Teams!G:G) -> 19 | G4: =SUMIF(Spieler_Teams!$A:$A,$A4,Spieler_Teams!H:H) -> 80 | H4: =SUMIF(Spieler_Teams!$A:$A,$A4,Spieler_Teams!I:I) -> 40 | I4: =SUMIF(Spieler_Teams!$A:$A,$A4,Spieler_Teams!J:J) -> 30 | J4: =SUMIF(Spieler_Teams!$A:$A,$A4,Spieler_Teams!K:K) -> 12 | K4: =SUMIF(Spieler_Teams!$A:$A,$A4,Spieler_Teams!L:L) -> 84 | L4: =SUMIF(Spieler_Teams!$A:$A,$A4,Spieler_Teams!M:M) -> 41 | M4: =SUMIF(Spieler_Teams!$A:$A,$A4,Spieler_Teams!N:N) -> 19 | N4: =SUMIF(Spieler_Teams!$A:$A,$A4,Spieler_Teams!O:O) -> 44 | O4: =SUMIF(Spieler_Teams!$A:$A,$A4,Spieler_Teams!P:P) -> 84 | P4: =SUMIF(Spieler_Teams!$A:$A,$A4,Spieler_Teams!Q:Q) -> 67 | Q4: =SUMIF(Spieler_Teams!$A:$A,$A4,Spieler_Teams!R:R) -> 54 | R4: =SUMIF(Spieler_Teams!$A:$A,$A4,Spieler_Teams!S:S) -> 25 | S4: =SUMIF(Spieler_Teams!$A:$A,$A4,Spieler_Teams!T:T) -> 59 | T4: =SUMIF(Spieler_Teams!$A:$A,$A4,Spieler_Teams!U:U) -> 62 | U4: =SUMIF(Spieler_Teams!$A:$A,$A4,Spieler_Teams!V:V) -> 63 | V4: =SUMIF(Spieler_Teams!$A:$A,$A4,Spieler_Teams!W:W) -> 10 | W4: =SUMIF(Spieler_Teams!$A:$A,$A4,Spieler_Teams!X:X) -> 270 | X4: =SUMIF(Spieler_Teams!$A:$A,$A4,Spieler_Teams!Y:Y) -> 44 | Y4: =SUMIF(Spieler_Teams!$A:$A,$A4,Spieler_Teams!Z:Z) -> 34 | Z4: =SUMIF(Spieler_Teams!$A:$A,$A4,Spieler_Teams!AA:AA) -> 10 | AA4: =SUMIF(Spieler_Teams!$A:$A,$A4,Spieler_Teams!AB:AB) -> 25
A5: Chris | B5: =SUMIF(Spieler_Teams!A:A,A5,Spieler_Teams!C:C) -> 61 | C5: =SUMIF(Spieler_Teams!$A:$A,$A5,Spieler_Teams!D:D) -> 48 | D5: =SUMIF(Spieler_Teams!$A:$A,$A5,Spieler_Teams!E:E) -> 68 | E5: =SUMIF(Spieler_Teams!$A:$A,$A5,Spieler_Teams!F:F) -> 6 | F5: =SUMIF(Spieler_Teams!$A:$A,$A5,Spieler_Teams!G:G) -> 26 | G5: =SUMIF(Spieler_Teams!$A:$A,$A5,Spieler_Teams!H:H) -> 65 | H5: =SUMIF(Spieler_Teams!$A:$A,$A5,Spieler_Teams!I:I) -> 41 | I5: =SUMIF(Spieler_Teams!$A:$A,$A5,Spieler_Teams!J:J) -> 42 | J5: =SUMIF(Spieler_Teams!$A:$A,$A5,Spieler_Teams!K:K) -> 10 | K5: =SUMIF(Spieler_Teams!$A:$A,$A5,Spieler_Teams!L:L) -> 63 | L5: =SUMIF(Spieler_Teams!$A:$A,$A5,Spieler_Teams!M:M) -> 21 | M5: =SUMIF(Spieler_Teams!$A:$A,$A5,Spieler_Teams!N:N) -> 45 | N5: =SUMIF(Spieler_Teams!$A:$A,$A5,Spieler_Teams!O:O) -> 13 | O5: =SUMIF(Spieler_Teams!$A:$A,$A5,Spieler_Teams!P:P) -> 65 | P5: =SUMIF(Spieler_Teams!$A:$A,$A5,Spieler_Teams!Q:Q) -> 39 | Q5: =SUMIF(Spieler_Teams!$A:$A,$A5,Spieler_Teams!R:R) -> 54 | R5: =SUMIF(Spieler_Teams!$A:$A,$A5,Spieler_Teams!S:S) -> 30 | S5: =SUMIF(Spieler_Teams!$A:$A,$A5,Spieler_Teams!T:T) -> 17 | T5: =SUMIF(Spieler_Teams!$A:$A,$A5,Spieler_Teams!U:U) -> 38 | U5: =SUMIF(Spieler_Teams!$A:$A,$A5,Spieler_Teams!V:V) -> 22 | V5: =SUMIF(Spieler_Teams!$A:$A,$A5,Spieler_Teams!W:W) -> 23 | W5: =SUMIF(Spieler_Teams!$A:$A,$A5,Spieler_Teams!X:X) -> 145 | X5: =SUMIF(Spieler_Teams!$A:$A,$A5,Spieler_Teams!Y:Y) -> 24 | Y5: =SUMIF(Spieler_Teams!$A:$A,$A5,Spieler_Teams!Z:Z) -> 26 | Z5: =SUMIF(Spieler_Teams!$A:$A,$A5,Spieler_Teams!AA:AA) -> 10 | AA5: =SUMIF(Spieler_Teams!$A:$A,$A5,Spieler_Teams!AB:AB) -> 25
A6: Nora | B6: =SUMIF(Spieler_Teams!A:A,A6,Spieler_Teams!C:C) -> 57 | C6: =SUMIF(Spieler_Teams!$A:$A,$A6,Spieler_Teams!D:D) -> 45 | D6: =SUMIF(Spieler_Teams!$A:$A,$A6,Spieler_Teams!E:E) -> 64 | E6: =SUMIF(Spieler_Teams!$A:$A,$A6,Spieler_Teams!F:F) -> 0 | F6: =SUMIF(Spieler_Teams!$A:$A,$A6,Spieler_Teams!G:G) -> 11 | G6: =SUMIF(Spieler_Teams!$A:$A,$A6,Spieler_Teams!H:H) -> 63 | H6: =SUMIF(Spieler_Teams!$A:$A,$A6,Spieler_Teams!I:I) -> 16 | I6: =SUMIF(Spieler_Teams!$A:$A,$A6,Spieler_Teams!J:J) -> 18 | J6: =SUMIF(Spieler_Teams!$A:$A,$A6,Spieler_Teams!K:K) -> 35 | K6: =SUMIF(Spieler_Teams!$A:$A,$A6,Spieler_Teams!L:L) -> 56 | L6: =SUMIF(Spieler_Teams!$A:$A,$A6,Spieler_Teams!M:M) -> 20 | M6: =SUMIF(Spieler_Teams!$A:$A,$A6,Spieler_Teams!N:N) -> 22 | N6: =SUMIF(Spieler_Teams!$A:$A,$A6,Spieler_Teams!O:O) -> 5 | O6: =SUMIF(Spieler_Teams!$A:$A,$A6,Spieler_Teams!P:P) -> 62 | P6: =SUMIF(Spieler_Teams!$A:$A,$A6,Spieler_Teams!Q:Q) -> 46 | Q6: =SUMIF(Spieler_Teams!$A:$A,$A6,Spieler_Teams!R:R) -> 49 | R6: =SUMIF(Spieler_Teams!$A:$A,$A6,Spieler_Teams!S:S) -> 35 | S6: =SUMIF(Spieler_Teams!$A:$A,$A6,Spieler_Teams!T:T) -> 8 | T6: =SUMIF(Spieler_Teams!$A:$A,$A6,Spieler_Teams!U:U) -> 42 | U6: =SUMIF(Spieler_Teams!$A:$A,$A6,Spieler_Teams!V:V) -> 21 | V6: =SUMIF(Spieler_Teams!$A:$A,$A6,Spieler_Teams!W:W) -> 48 | W6: =SUMIF(Spieler_Teams!$A:$A,$A6,Spieler_Teams!X:X) -> 135 | X6: =SUMIF(Spieler_Teams!$A:$A,$A6,Spieler_Teams!Y:Y) -> 24 | Y6: =SUMIF(Spieler_Teams!$A:$A,$A6,Spieler_Teams!Z:Z) -> 26 | Z6: =SUMIF(Spieler_Teams!$A:$A,$A6,Spieler_Teams!AA:AA) -> 10 | AA6: =SUMIF(Spieler_Teams!$A:$A,$A6,Spieler_Teams!AB:AB) -> 25
A7: Lea | B7: =SUMIF(Spieler_Teams!A:A,A7,Spieler_Teams!C:C) -> 55 | C7: =SUMIF(Spieler_Teams!$A:$A,$A7,Spieler_Teams!D:D) -> 46 | D7: =SUMIF(Spieler_Teams!$A:$A,$A7,Spieler_Teams!E:E) -> 68 | E7: =SUMIF(Spieler_Teams!$A:$A,$A7,Spieler_Teams!F:F) -> 21 | F7: =SUMIF(Spieler_Teams!$A:$A,$A7,Spieler_Teams!G:G) -> 21 | G7: =SUMIF(Spieler_Teams!$A:$A,$A7,Spieler_Teams!H:H) -> 56 | H7: =SUMIF(Spieler_Teams!$A:$A,$A7,Spieler_Teams!I:I) -> 31 | I7: =SUMIF(Spieler_Teams!$A:$A,$A7,Spieler_Teams!J:J) -> 37 | J7: =SUMIF(Spieler_Teams!$A:$A,$A7,Spieler_Teams!K:K) -> 10 | K7: =SUMIF(Spieler_Teams!$A:$A,$A7,Spieler_Teams!L:L) -> 55 | L7: =SUMIF(Spieler_Teams!$A:$A,$A7,Spieler_Teams!M:M) -> 29 | M7: =SUMIF(Spieler_Teams!$A:$A,$A7,Spieler_Teams!N:N) -> 32 | N7: =SUMIF(Spieler_Teams!$A:$A,$A7,Spieler_Teams!O:O) -> 5 | O7: =SUMIF(Spieler_Teams!$A:$A,$A7,Spieler_Teams!P:P) -> 55 | P7: =SUMIF(Spieler_Teams!$A:$A,$A7,Spieler_Teams!Q:Q) -> 44 | Q7: =SUMIF(Spieler_Teams!$A:$A,$A7,Spieler_Teams!R:R) -> 35 | R7: =SUMIF(Spieler_Teams!$A:$A,$A7,Spieler_Teams!S:S) -> 30 | S7: =SUMIF(Spieler_Teams!$A:$A,$A7,Spieler_Teams!T:T) -> 40 | T7: =SUMIF(Spieler_Teams!$A:$A,$A7,Spieler_Teams!U:U) -> 69 | U7: =SUMIF(Spieler_Teams!$A:$A,$A7,Spieler_Teams!V:V) -> 53 | V7: =SUMIF(Spieler_Teams!$A:$A,$A7,Spieler_Teams!W:W) -> 30 | W7: =SUMIF(Spieler_Teams!$A:$A,$A7,Spieler_Teams!X:X) -> 180 | X7: =SUMIF(Spieler_Teams!$A:$A,$A7,Spieler_Teams!Y:Y) -> 46 | Y7: =SUMIF(Spieler_Teams!$A:$A,$A7,Spieler_Teams!Z:Z) -> 42 | Z7: =SUMIF(Spieler_Teams!$A:$A,$A7,Spieler_Teams!AA:AA) -> 5 | AA7: =SUMIF(Spieler_Teams!$A:$A,$A7,Spieler_Teams!AB:AB) -> 0
A8: Lanci | B8: =SUMIF(Spieler_Teams!A:A,A8,Spieler_Teams!C:C) -> 54 | C8: =SUMIF(Spieler_Teams!$A:$A,$A8,Spieler_Teams!D:D) -> 59 | D8: =SUMIF(Spieler_Teams!$A:$A,$A8,Spieler_Teams!E:E) -> 68 | E8: =SUMIF(Spieler_Teams!$A:$A,$A8,Spieler_Teams!F:F) -> 30 | F8: =SUMIF(Spieler_Teams!$A:$A,$A8,Spieler_Teams!G:G) -> 12 | G8: =SUMIF(Spieler_Teams!$A:$A,$A8,Spieler_Teams!H:H) -> 75 | H8: =SUMIF(Spieler_Teams!$A:$A,$A8,Spieler_Teams!I:I) -> 22 | I8: =SUMIF(Spieler_Teams!$A:$A,$A8,Spieler_Teams!J:J) -> 25 | J8: =SUMIF(Spieler_Teams!$A:$A,$A8,Spieler_Teams!K:K) -> 25 | K8: =SUMIF(Spieler_Teams!$A:$A,$A8,Spieler_Teams!L:L) -> 74 | L8: =SUMIF(Spieler_Teams!$A:$A,$A8,Spieler_Teams!M:M) -> 14 | M8: =SUMIF(Spieler_Teams!$A:$A,$A8,Spieler_Teams!N:N) -> 17 | N8: =SUMIF(Spieler_Teams!$A:$A,$A8,Spieler_Teams!O:O) -> 30 | O8: =SUMIF(Spieler_Teams!$A:$A,$A8,Spieler_Teams!P:P) -> 63 | P8: =SUMIF(Spieler_Teams!$A:$A,$A8,Spieler_Teams!Q:Q) -> 64 | Q8: =SUMIF(Spieler_Teams!$A:$A,$A8,Spieler_Teams!R:R) -> 44 | R8: =SUMIF(Spieler_Teams!$A:$A,$A8,Spieler_Teams!S:S) -> 5 | S8: =SUMIF(Spieler_Teams!$A:$A,$A8,Spieler_Teams!T:T) -> 23 | T8: =SUMIF(Spieler_Teams!$A:$A,$A8,Spieler_Teams!U:U) -> 55 | U8: =SUMIF(Spieler_Teams!$A:$A,$A8,Spieler_Teams!V:V) -> 32 | V8: =SUMIF(Spieler_Teams!$A:$A,$A8,Spieler_Teams!W:W) -> 10 | W8: =SUMIF(Spieler_Teams!$A:$A,$A8,Spieler_Teams!X:X) -> 210 | X8: =SUMIF(Spieler_Teams!$A:$A,$A8,Spieler_Teams!Y:Y) -> 26 | Y8: =SUMIF(Spieler_Teams!$A:$A,$A8,Spieler_Teams!Z:Z) -> 24 | Z8: =SUMIF(Spieler_Teams!$A:$A,$A8,Spieler_Teams!AA:AA) -> 5 | AA8: =SUMIF(Spieler_Teams!$A:$A,$A8,Spieler_Teams!AB:AB) -> 0
A9: Sebbo | B9: =SUMIF(Spieler_Teams!A:A,A9,Spieler_Teams!C:C) -> 53 | C9: =SUMIF(Spieler_Teams!$A:$A,$A9,Spieler_Teams!D:D) -> 77 | D9: =SUMIF(Spieler_Teams!$A:$A,$A9,Spieler_Teams!E:E) -> 76 | E9: =SUMIF(Spieler_Teams!$A:$A,$A9,Spieler_Teams!F:F) -> 10 | F9: =SUMIF(Spieler_Teams!$A:$A,$A9,Spieler_Teams!G:G) -> 14 | G9: =SUMIF(Spieler_Teams!$A:$A,$A9,Spieler_Teams!H:H) -> 66 | H9: =SUMIF(Spieler_Teams!$A:$A,$A9,Spieler_Teams!I:I) -> 26 | I9: =SUMIF(Spieler_Teams!$A:$A,$A9,Spieler_Teams!J:J) -> 37 | J9: =SUMIF(Spieler_Teams!$A:$A,$A9,Spieler_Teams!K:K) -> 35 | K9: =SUMIF(Spieler_Teams!$A:$A,$A9,Spieler_Teams!L:L) -> 63 | L9: =SUMIF(Spieler_Teams!$A:$A,$A9,Spieler_Teams!M:M) -> 22 | M9: =SUMIF(Spieler_Teams!$A:$A,$A9,Spieler_Teams!N:N) -> 20 | N9: =SUMIF(Spieler_Teams!$A:$A,$A9,Spieler_Teams!O:O) -> 18 | O9: =SUMIF(Spieler_Teams!$A:$A,$A9,Spieler_Teams!P:P) -> 76 | P9: =SUMIF(Spieler_Teams!$A:$A,$A9,Spieler_Teams!Q:Q) -> 61 | Q9: =SUMIF(Spieler_Teams!$A:$A,$A9,Spieler_Teams!R:R) -> 38 | R9: =SUMIF(Spieler_Teams!$A:$A,$A9,Spieler_Teams!S:S) -> 7 | S9: =SUMIF(Spieler_Teams!$A:$A,$A9,Spieler_Teams!T:T) -> 25 | T9: =SUMIF(Spieler_Teams!$A:$A,$A9,Spieler_Teams!U:U) -> 50 | U9: =SUMIF(Spieler_Teams!$A:$A,$A9,Spieler_Teams!V:V) -> 41 | V9: =SUMIF(Spieler_Teams!$A:$A,$A9,Spieler_Teams!W:W) -> 10 | W9: =SUMIF(Spieler_Teams!$A:$A,$A9,Spieler_Teams!X:X) -> 205 | X9: =SUMIF(Spieler_Teams!$A:$A,$A9,Spieler_Teams!Y:Y) -> 32 | Y9: =SUMIF(Spieler_Teams!$A:$A,$A9,Spieler_Teams!Z:Z) -> 28 | Z9: =SUMIF(Spieler_Teams!$A:$A,$A9,Spieler_Teams!AA:AA) -> 15 | AA9: =SUMIF(Spieler_Teams!$A:$A,$A9,Spieler_Teams!AB:AB) -> 0
A10: Bendix | B10: =SUMIF(Spieler_Teams!A:A,A10,Spieler_Teams!C:C) -> 53 | C10: =SUMIF(Spieler_Teams!$A:$A,$A10,Spieler_Teams!D:D) -> 35 | D10: =SUMIF(Spieler_Teams!$A:$A,$A10,Spieler_Teams!E:E) -> 59 | E10: =SUMIF(Spieler_Teams!$A:$A,$A10,Spieler_Teams!F:F) -> 2 | F10: =SUMIF(Spieler_Teams!$A:$A,$A10,Spieler_Teams!G:G) -> 25 | G10: =SUMIF(Spieler_Teams!$A:$A,$A10,Spieler_Teams!H:H) -> 60 | H10: =SUMIF(Spieler_Teams!$A:$A,$A10,Spieler_Teams!I:I) -> 45 | I10: =SUMIF(Spieler_Teams!$A:$A,$A10,Spieler_Teams!J:J) -> 50 | J10: =SUMIF(Spieler_Teams!$A:$A,$A10,Spieler_Teams!K:K) -> 10 | K10: =SUMIF(Spieler_Teams!$A:$A,$A10,Spieler_Teams!L:L) -> 51 | L10: =SUMIF(Spieler_Teams!$A:$A,$A10,Spieler_Teams!M:M) -> 15 | M10: =SUMIF(Spieler_Teams!$A:$A,$A10,Spieler_Teams!N:N) -> 42 | N10: =SUMIF(Spieler_Teams!$A:$A,$A10,Spieler_Teams!O:O) -> 27 | O10: =SUMIF(Spieler_Teams!$A:$A,$A10,Spieler_Teams!P:P) -> 52 | P10: =SUMIF(Spieler_Teams!$A:$A,$A10,Spieler_Teams!Q:Q) -> 36 | Q10: =SUMIF(Spieler_Teams!$A:$A,$A10,Spieler_Teams!R:R) -> 28 | R10: =SUMIF(Spieler_Teams!$A:$A,$A10,Spieler_Teams!S:S) -> 5 | S10: =SUMIF(Spieler_Teams!$A:$A,$A10,Spieler_Teams!T:T) -> 8 | T10: =SUMIF(Spieler_Teams!$A:$A,$A10,Spieler_Teams!U:U) -> 28 | U10: =SUMIF(Spieler_Teams!$A:$A,$A10,Spieler_Teams!V:V) -> 15 | V10: =SUMIF(Spieler_Teams!$A:$A,$A10,Spieler_Teams!W:W) -> 12 | W10: =SUMIF(Spieler_Teams!$A:$A,$A10,Spieler_Teams!X:X) -> 75 | X10: =SUMIF(Spieler_Teams!$A:$A,$A10,Spieler_Teams!Y:Y) -> 18 | Y10: =SUMIF(Spieler_Teams!$A:$A,$A10,Spieler_Teams!Z:Z) -> 24 | Z10: =SUMIF(Spieler_Teams!$A:$A,$A10,Spieler_Teams!AA:AA) -> 0 | AA10: =SUMIF(Spieler_Teams!$A:$A,$A10,Spieler_Teams!AB:AB) -> 0
A11: Till | B11: =SUMIF(Spieler_Teams!A:A,A11,Spieler_Teams!C:C) -> 52 | C11: =SUMIF(Spieler_Teams!$A:$A,$A11,Spieler_Teams!D:D) -> 55 | D11: =SUMIF(Spieler_Teams!$A:$A,$A11,Spieler_Teams!E:E) -> 75 | E11: =SUMIF(Spieler_Teams!$A:$A,$A11,Spieler_Teams!F:F) -> 25 | F11: =SUMIF(Spieler_Teams!$A:$A,$A11,Spieler_Teams!G:G) -> 18 | G11: =SUMIF(Spieler_Teams!$A:$A,$A11,Spieler_Teams!H:H) -> 63 | H11: =SUMIF(Spieler_Teams!$A:$A,$A11,Spieler_Teams!I:I) -> 38 | I11: =SUMIF(Spieler_Teams!$A:$A,$A11,Spieler_Teams!J:J) -> 32 | J11: =SUMIF(Spieler_Teams!$A:$A,$A11,Spieler_Teams!K:K) -> 30 | K11: =SUMIF(Spieler_Teams!$A:$A,$A11,Spieler_Teams!L:L) -> 56 | L11: =SUMIF(Spieler_Teams!$A:$A,$A11,Spieler_Teams!M:M) -> 6 | M11: =SUMIF(Spieler_Teams!$A:$A,$A11,Spieler_Teams!N:N) -> 34 | N11: =SUMIF(Spieler_Teams!$A:$A,$A11,Spieler_Teams!O:O) -> 15 | O11: =SUMIF(Spieler_Teams!$A:$A,$A11,Spieler_Teams!P:P) -> 68 | P11: =SUMIF(Spieler_Teams!$A:$A,$A11,Spieler_Teams!Q:Q) -> 39 | Q11: =SUMIF(Spieler_Teams!$A:$A,$A11,Spieler_Teams!R:R) -> 46 | R11: =SUMIF(Spieler_Teams!$A:$A,$A11,Spieler_Teams!S:S) -> 8 | S11: =SUMIF(Spieler_Teams!$A:$A,$A11,Spieler_Teams!T:T) -> 28 | T11: =SUMIF(Spieler_Teams!$A:$A,$A11,Spieler_Teams!U:U) -> 49 | U11: =SUMIF(Spieler_Teams!$A:$A,$A11,Spieler_Teams!V:V) -> 26 | V11: =SUMIF(Spieler_Teams!$A:$A,$A11,Spieler_Teams!W:W) -> 13 | W11: =SUMIF(Spieler_Teams!$A:$A,$A11,Spieler_Teams!X:X) -> 155 | X11: =SUMIF(Spieler_Teams!$A:$A,$A11,Spieler_Teams!Y:Y) -> 28 | Y11: =SUMIF(Spieler_Teams!$A:$A,$A11,Spieler_Teams!Z:Z) -> 8 | Z11: =SUMIF(Spieler_Teams!$A:$A,$A11,Spieler_Teams!AA:AA) -> 10 | AA11: =SUMIF(Spieler_Teams!$A:$A,$A11,Spieler_Teams!AB:AB) -> 25
A12: Reto | B12: =SUMIF(Spieler_Teams!A:A,A12,Spieler_Teams!C:C) -> 50 | C12: =SUMIF(Spieler_Teams!$A:$A,$A12,Spieler_Teams!D:D) -> 48 | D12: =SUMIF(Spieler_Teams!$A:$A,$A12,Spieler_Teams!E:E) -> 65 | E12: =SUMIF(Spieler_Teams!$A:$A,$A12,Spieler_Teams!F:F) -> 0 | F12: =SUMIF(Spieler_Teams!$A:$A,$A12,Spieler_Teams!G:G) -> 46 | G12: =SUMIF(Spieler_Teams!$A:$A,$A12,Spieler_Teams!H:H) -> 62 | H12: =SUMIF(Spieler_Teams!$A:$A,$A12,Spieler_Teams!I:I) -> 53 | I12: =SUMIF(Spieler_Teams!$A:$A,$A12,Spieler_Teams!J:J) -> 50 | J12: =SUMIF(Spieler_Teams!$A:$A,$A12,Spieler_Teams!K:K) -> 46 | K12: =SUMIF(Spieler_Teams!$A:$A,$A12,Spieler_Teams!L:L) -> 67 | L12: =SUMIF(Spieler_Teams!$A:$A,$A12,Spieler_Teams!M:M) -> 21 | M12: =SUMIF(Spieler_Teams!$A:$A,$A12,Spieler_Teams!N:N) -> 56 | N12: =SUMIF(Spieler_Teams!$A:$A,$A12,Spieler_Teams!O:O) -> 5 | O12: =SUMIF(Spieler_Teams!$A:$A,$A12,Spieler_Teams!P:P) -> 66 | P12: =SUMIF(Spieler_Teams!$A:$A,$A12,Spieler_Teams!Q:Q) -> 60 | Q12: =SUMIF(Spieler_Teams!$A:$A,$A12,Spieler_Teams!R:R) -> 57 | R12: =SUMIF(Spieler_Teams!$A:$A,$A12,Spieler_Teams!S:S) -> 35 | S12: =SUMIF(Spieler_Teams!$A:$A,$A12,Spieler_Teams!T:T) -> 42 | T12: =SUMIF(Spieler_Teams!$A:$A,$A12,Spieler_Teams!U:U) -> 92 | U12: =SUMIF(Spieler_Teams!$A:$A,$A12,Spieler_Teams!V:V) -> 80 | V12: =SUMIF(Spieler_Teams!$A:$A,$A12,Spieler_Teams!W:W) -> 64 | W12: =SUMIF(Spieler_Teams!$A:$A,$A12,Spieler_Teams!X:X) -> 295 | X12: =SUMIF(Spieler_Teams!$A:$A,$A12,Spieler_Teams!Y:Y) -> 66 | Y12: =SUMIF(Spieler_Teams!$A:$A,$A12,Spieler_Teams!Z:Z) -> 40 | Z12: =SUMIF(Spieler_Teams!$A:$A,$A12,Spieler_Teams!AA:AA) -> 15 | AA12: =SUMIF(Spieler_Teams!$A:$A,$A12,Spieler_Teams!AB:AB) -> 20
A13: Konsti | B13: =SUMIF(Spieler_Teams!A:A,A13,Spieler_Teams!C:C) -> 50 | C13: =SUMIF(Spieler_Teams!$A:$A,$A13,Spieler_Teams!D:D) -> 62 | D13: =SUMIF(Spieler_Teams!$A:$A,$A13,Spieler_Teams!E:E) -> 45 | E13: =SUMIF(Spieler_Teams!$A:$A,$A13,Spieler_Teams!F:F) -> 10 | F13: =SUMIF(Spieler_Teams!$A:$A,$A13,Spieler_Teams!G:G) -> 20 | G13: =SUMIF(Spieler_Teams!$A:$A,$A13,Spieler_Teams!H:H) -> 60 | H13: =SUMIF(Spieler_Teams!$A:$A,$A13,Spieler_Teams!I:I) -> 14 | I13: =SUMIF(Spieler_Teams!$A:$A,$A13,Spieler_Teams!J:J) -> 9 | J13: =SUMIF(Spieler_Teams!$A:$A,$A13,Spieler_Teams!K:K) -> 26 | K13: =SUMIF(Spieler_Teams!$A:$A,$A13,Spieler_Teams!L:L) -> 74 | L13: =SUMIF(Spieler_Teams!$A:$A,$A13,Spieler_Teams!M:M) -> 2 | M13: =SUMIF(Spieler_Teams!$A:$A,$A13,Spieler_Teams!N:N) -> 11 | N13: =SUMIF(Spieler_Teams!$A:$A,$A13,Spieler_Teams!O:O) -> 27 | O13: =SUMIF(Spieler_Teams!$A:$A,$A13,Spieler_Teams!P:P) -> 67 | P13: =SUMIF(Spieler_Teams!$A:$A,$A13,Spieler_Teams!Q:Q) -> 76 | Q13: =SUMIF(Spieler_Teams!$A:$A,$A13,Spieler_Teams!R:R) -> 54 | R13: =SUMIF(Spieler_Teams!$A:$A,$A13,Spieler_Teams!S:S) -> 2 | S13: =SUMIF(Spieler_Teams!$A:$A,$A13,Spieler_Teams!T:T) -> 20 | T13: =SUMIF(Spieler_Teams!$A:$A,$A13,Spieler_Teams!U:U) -> 29 | U13: =SUMIF(Spieler_Teams!$A:$A,$A13,Spieler_Teams!V:V) -> 47 | V13: =SUMIF(Spieler_Teams!$A:$A,$A13,Spieler_Teams!W:W) -> 14 | W13: =SUMIF(Spieler_Teams!$A:$A,$A13,Spieler_Teams!X:X) -> 270 | X13: =SUMIF(Spieler_Teams!$A:$A,$A13,Spieler_Teams!Y:Y) -> 28 | Y13: =SUMIF(Spieler_Teams!$A:$A,$A13,Spieler_Teams!Z:Z) -> 24 | Z13: =SUMIF(Spieler_Teams!$A:$A,$A13,Spieler_Teams!AA:AA) -> 25 | AA13: =SUMIF(Spieler_Teams!$A:$A,$A13,Spieler_Teams!AB:AB) -> 0
A14: Jule | B14: =SUMIF(Spieler_Teams!A:A,A14,Spieler_Teams!C:C) -> 40 | C14: =SUMIF(Spieler_Teams!$A:$A,$A14,Spieler_Teams!D:D) -> 53 | D14: =SUMIF(Spieler_Teams!$A:$A,$A14,Spieler_Teams!E:E) -> 73 | E14: =SUMIF(Spieler_Teams!$A:$A,$A14,Spieler_Teams!F:F) -> 10 | F14: =SUMIF(Spieler_Teams!$A:$A,$A14,Spieler_Teams!G:G) -> 31 | G14: =SUMIF(Spieler_Teams!$A:$A,$A14,Spieler_Teams!H:H) -> 54 | H14: =SUMIF(Spieler_Teams!$A:$A,$A14,Spieler_Teams!I:I) -> 28 | I14: =SUMIF(Spieler_Teams!$A:$A,$A14,Spieler_Teams!J:J) -> 24 | J14: =SUMIF(Spieler_Teams!$A:$A,$A14,Spieler_Teams!K:K) -> 14 | K14: =SUMIF(Spieler_Teams!$A:$A,$A14,Spieler_Teams!L:L) -> 69 | L14: =SUMIF(Spieler_Teams!$A:$A,$A14,Spieler_Teams!M:M) -> 20 | M14: =SUMIF(Spieler_Teams!$A:$A,$A14,Spieler_Teams!N:N) -> 29 | N14: =SUMIF(Spieler_Teams!$A:$A,$A14,Spieler_Teams!O:O) -> 15 | O14: =SUMIF(Spieler_Teams!$A:$A,$A14,Spieler_Teams!P:P) -> 61 | P14: =SUMIF(Spieler_Teams!$A:$A,$A14,Spieler_Teams!Q:Q) -> 67 | Q14: =SUMIF(Spieler_Teams!$A:$A,$A14,Spieler_Teams!R:R) -> 52 | R14: =SUMIF(Spieler_Teams!$A:$A,$A14,Spieler_Teams!S:S) -> 30 | S14: =SUMIF(Spieler_Teams!$A:$A,$A14,Spieler_Teams!T:T) -> 53 | T14: =SUMIF(Spieler_Teams!$A:$A,$A14,Spieler_Teams!U:U) -> 57 | U14: =SUMIF(Spieler_Teams!$A:$A,$A14,Spieler_Teams!V:V) -> 62 | V14: =SUMIF(Spieler_Teams!$A:$A,$A14,Spieler_Teams!W:W) -> 37 | W14: =SUMIF(Spieler_Teams!$A:$A,$A14,Spieler_Teams!X:X) -> 185 | X14: =SUMIF(Spieler_Teams!$A:$A,$A14,Spieler_Teams!Y:Y) -> 66 | Y14: =SUMIF(Spieler_Teams!$A:$A,$A14,Spieler_Teams!Z:Z) -> 46 | Z14: =SUMIF(Spieler_Teams!$A:$A,$A14,Spieler_Teams!AA:AA) -> 0 | AA14: =SUMIF(Spieler_Teams!$A:$A,$A14,Spieler_Teams!AB:AB) -> 25
... A18: Simi | B18: =SUMIF(Spieler_Teams!A:A,A18,Spieler_Teams!C:C) -> 25 | C18: =SUMIF(Spieler_Teams!$A:$A,$A18,Spieler_Teams!D:D) -> 47 | D18: =SUMIF(Spieler_Teams!$A:$A,$A18,Spieler_Teams!E:E) -> 58 | E18: =SUMIF(Spieler_Teams!$A:$A,$A18,Spieler_Teams!F:F) -> 27 | F18: =SUMIF(Spieler_Teams!$A:$A,$A18,Spieler_Teams!G:G) -> 48 | G18: =SUMIF(Spieler_Teams!$A:$A,$A18,Spieler_Teams!H:H) -> 51 | H18: =SUMIF(Spieler_Teams!$A:$A,$A18,Spieler_Teams!I:I) -> 33 | I18: =SUMIF(Spieler_Teams!$A:$A,$A18,Spieler_Teams!J:J) -> 40 | J18: =SUMIF(Spieler_Teams!$A:$A,$A18,Spieler_Teams!K:K) -> 41 | K18: =SUMIF(Spieler_Teams!$A:$A,$A18,Spieler_Teams!L:L) -> 56 | L18: =SUMIF(Spieler_Teams!$A:$A,$A18,Spieler_Teams!M:M) -> 47 | M18: =SUMIF(Spieler_Teams!$A:$A,$A18,Spieler_Teams!N:N) -> 49 | N18: =SUMIF(Spieler_Teams!$A:$A,$A18,Spieler_Teams!O:O) -> 26 | O18: =SUMIF(Spieler_Teams!$A:$A,$A18,Spieler_Teams!P:P) -> 63 | P18: =SUMIF(Spieler_Teams!$A:$A,$A18,Spieler_Teams!Q:Q) -> 50 | Q18: =SUMIF(Spieler_Teams!$A:$A,$A18,Spieler_Teams!R:R) -> 51 | R18: =SUMIF(Spieler_Teams!$A:$A,$A18,Spieler_Teams!S:S) -> 55 | S18: =SUMIF(Spieler_Teams!$A:$A,$A18,Spieler_Teams!T:T) -> 40 | T18: =SUMIF(Spieler_Teams!$A:$A,$A18,Spieler_Teams!U:U) -> 75 | U18: =SUMIF(Spieler_Teams!$A:$A,$A18,Spieler_Teams!V:V) -> 38 | V18: =SUMIF(Spieler_Teams!$A:$A,$A18,Spieler_Teams!W:W) -> 51 | W18: =SUMIF(Spieler_Teams!$A:$A,$A18,Spieler_Teams!X:X) -> 210 | X18: =SUMIF(Spieler_Teams!$A:$A,$A18,Spieler_Teams!Y:Y) -> 52 | Y18: =SUMIF(Spieler_Teams!$A:$A,$A18,Spieler_Teams!Z:Z) -> 58 | Z18: =SUMIF(Spieler_Teams!$A:$A,$A18,Spieler_Teams!AA:AA) -> 15 | AA18: =SUMIF(Spieler_Teams!$A:$A,$A18,Spieler_Teams!AB:AB) -> 25

Sheet Spieler_Teams
A1: Spieler | B1: Fahrer | C1: Stage01 | D1: Stage02 | E1: Stage03 | F1: Stage04 | G1: Stage05 | H1: Stage06 | I1: Stage07 | J1: Stage08 | K1: Stage09 | L1: Stage10 | M1: Stage11 | N1: Stage12 | O1: Stage13 | P1: Stage14 | Q1: Stage15 | R1: Stage16 | S1: Stage17 | T1: Stage18 | U1: Stage19 | V1: Stage20 | W1: Stage21 | X1: S 22 GC | Y1: S 23 Mountain | Z1: S 24 Sprint | AA1: S 25 Youth | AB1: S 26 TeamRank
A2: Reto | B2: =Startlist2026!D2 -> PogačarTadejUAE Team Emirates - XRG | C2: =SUMIF(Ergebnisse_Roh!C$2:C$21,$B2,Punktematrix!$B$2:$B$21) -> 17 | D2: =SUMIF(Ergebnisse_Roh!D$2:D$21,$B2,Punktematrix!$B$2:$B$21) -> 20 | E2: =SUMIF(Ergebnisse_Roh!E$2:E$21,$B2,Punktematrix!$B$2:$B$21) -> 30 | F2: =SUMIF(Ergebnisse_Roh!F$2:F$21,$B2,Punktematrix!$B$2:$B$21) -> 0 | G2: =SUMIF(Ergebnisse_Roh!G$2:G$21,$B2,Punktematrix!$B$2:$B$21) -> 0 | H2: =SUMIF(Ergebnisse_Roh!H$2:H$21,$B2,Punktematrix!$B$2:$B$21) -> 30 | I2: =SUMIF(Ergebnisse_Roh!I$2:I$21,$B2,Punktematrix!$B$2:$B$21) -> 5 | J2: =SUMIF(Ergebnisse_Roh!J$2:J$21,$B2,Punktematrix!$B$2:$B$21) -> 5 | ... W2: =SUMIF(Ergebnisse_Roh!W$2:W$21,$B2,Punktematrix!$B$2:$B$21) -> 3 | X2: =SUMIF(Ergebnisse_Roh!X$2:X$16,$B2,Punktematrix!$C$2:$C$16) -> 75 | Y2: =SUMIF(Ergebnisse_Roh!Y$2:Y$11,$B2,Punktematrix!$D$2:$D$11) -> 18 | Z2: =SUMIF(Ergebnisse_Roh!Z$2:Z$11,$B2,Punktematrix!$E$2:$E$11) -> 8 | AA2: =SUMIF(Ergebnisse_Roh!AA$2:AA$4,$B2,Punktematrix!$F$2:$F$4) -> 0 | AB2: =SUMIF(Ergebnisse_Roh!AB$2:AB$4,$B2,Punktematrix!$G$2:$G$4) -> 0
A3: Reto | B3: =Startlist2026!D82 -> van der PoelMathieuAlpecin - Premier Tech | C3: =SUMIF(Ergebnisse_Roh!C$2:C$21,$B3,Punktematrix!$B$2:$B$21) -> 5 | D3: =SUMIF(Ergebnisse_Roh!D$2:D$21,$B3,Punktematrix!$B$2:$B$21) -> 0 | E3: =SUMIF(Ergebnisse_Roh!E$2:E$21,$B3,Punktematrix!$B$2:$B$21) -> 0 | F3: =SUMIF(Ergebnisse_Roh!F$2:F$21,$B3,Punktematrix!$B$2:$B$21) -> 0 | G3: =SUMIF(Ergebnisse_Roh!G$2:G$21,$B3,Punktematrix!$B$2:$B$21) -> 0 | H3: =SUMIF(Ergebnisse_Roh!H$2:H$21,$B3,Punktematrix!$B$2:$B$21) -> 0 | I3: =SUMIF(Ergebnisse_Roh!I$2:I$21,$B3,Punktematrix!$B$2:$B$21) -> 0 | J3: =SUMIF(Ergebnisse_Roh!J$2:J$21,$B3,Punktematrix!$B$2:$B$21) -> 1 | ... W3: =SUMIF(Ergebnisse_Roh!W$2:W$21,$B3,Punktematrix!$B$2:$B$21) -> 25 | X3: =SUMIF(Ergebnisse_Roh!X$2:X$16,$B3,Punktematrix!$C$2:$C$16) -> 0 | Y3: =SUMIF(Ergebnisse_Roh!Y$2:Y$11,$B3,Punktematrix!$D$2:$D$11) -> 0 | Z3: =SUMIF(Ergebnisse_Roh!Z$2:Z$11,$B3,Punktematrix!$E$2:$E$11) -> 0 | AA3: =SUMIF(Ergebnisse_Roh!AA$2:AA$4,$B3,Punktematrix!$F$2:$F$4) -> 0 | AB3: =SUMIF(Ergebnisse_Roh!AB$2:AB$4,$B3,Punktematrix!$G$2:$G$4) -> 0
A4: Reto | B4: =Startlist2026!D58 -> MartinezLennyBahrain - Victorious | C4: =SUMIF(Ergebnisse_Roh!C$2:C$21,$B4,Punktematrix!$B$2:$B$21) -> 1 | D4: =SUMIF(Ergebnisse_Roh!D$2:D$21,$B4,Punktematrix!$B$2:$B$21) -> 7 | E4: =SUMIF(Ergebnisse_Roh!E$2:E$21,$B4,Punktematrix!$B$2:$B$21) -> 3 | F4: =SUMIF(Ergebnisse_Roh!F$2:F$21,$B4,Punktematrix!$B$2:$B$21) -> 0 | G4: =SUMIF(Ergebnisse_Roh!G$2:G$21,$B4,Punktematrix!$B$2:$B$21) -> 0 | H4: =SUMIF(Ergebnisse_Roh!H$2:H$21,$B4,Punktematrix!$B$2:$B$21) -> 6 | I4: =SUMIF(Ergebnisse_Roh!I$2:I$21,$B4,Punktematrix!$B$2:$B$21) -> 0 | J4: =SUMIF(Ergebnisse_Roh!J$2:J$21,$B4,Punktematrix!$B$2:$B$21) -> 0 | ... W4: =SUMIF(Ergebnisse_Roh!W$2:W$21,$B4,Punktematrix!$B$2:$B$21) -> 0 | X4: =SUMIF(Ergebnisse_Roh!X$2:X$16,$B4,Punktematrix!$C$2:$C$16) -> 55 | Y4: =SUMIF(Ergebnisse_Roh!Y$2:Y$11,$B4,Punktematrix!$D$2:$D$11) -> 8 | Z4: =SUMIF(Ergebnisse_Roh!Z$2:Z$11,$B4,Punktematrix!$E$2:$E$11) -> 0 | AA4: =SUMIF(Ergebnisse_Roh!AA$2:AA$4,$B4,Punktematrix!$F$2:$F$4) -> 5 | AB4: =SUMIF(Ergebnisse_Roh!AB$2:AB$4,$B4,Punktematrix!$G$2:$G$4) -> 0
A5: Reto | B5: =Startlist2026!D16 -> KussSeppTeam Visma | Lease a Bike | C5: =SUMIF(Ergebnisse_Roh!C$2:C$21,$B5,Punktematrix!$B$2:$B$21) -> 0 | D5: =SUMIF(Ergebnisse_Roh!D$2:D$21,$B5,Punktematrix!$B$2:$B$21) -> 0 | E5: =SUMIF(Ergebnisse_Roh!E$2:E$21,$B5,Punktematrix!$B$2:$B$21) -> 0 | F5: =SUMIF(Ergebnisse_Roh!F$2:F$21,$B5,Punktematrix!$B$2:$B$21) -> 0 | G5: =SUMIF(Ergebnisse_Roh!G$2:G$21,$B5,Punktematrix!$B$2:$B$21) -> 0 | H5: =SUMIF(Ergebnisse_Roh!H$2:H$21,$B5,Punktematrix!$B$2:$B$21) -> 7 | I5: =SUMIF(Ergebnisse_Roh!I$2:I$21,$B5,Punktematrix!$B$2:$B$21) -> 0 | J5: =SUMIF(Ergebnisse_Roh!J$2:J$21,$B5,Punktematrix!$B$2:$B$21) -> 0 | ... W5: =SUMIF(Ergebnisse_Roh!W$2:W$21,$B5,Punktematrix!$B$2:$B$21) -> 0 | X5: =SUMIF(Ergebnisse_Roh!X$2:X$16,$B5,Punktematrix!$C$2:$C$16) -> 15 | Y5: =SUMIF(Ergebnisse_Roh!Y$2:Y$11,$B5,Punktematrix!$D$2:$D$11) -> 14 | Z5: =SUMIF(Ergebnisse_Roh!Z$2:Z$11,$B5,Punktematrix!$E$2:$E$11) -> 0 | AA5: =SUMIF(Ergebnisse_Roh!AA$2:AA$4,$B5,Punktematrix!$F$2:$F$4) -> 0 | AB5: =SUMIF(Ergebnisse_Roh!AB$2:AB$4,$B5,Punktematrix!$G$2:$G$4) -> 0
A6: Reto | B6: =Startlist2026!D69 -> GannaFilippoNetcompany INEOS | C6: =SUMIF(Ergebnisse_Roh!C$2:C$21,$B6,Punktematrix!$B$2:$B$21) -> 20 | D6: =SUMIF(Ergebnisse_Roh!D$2:D$21,$B6,Punktematrix!$B$2:$B$21) -> 0 | E6: =SUMIF(Ergebnisse_Roh!E$2:E$21,$B6,Punktematrix!$B$2:$B$21) -> 0 | F6: =SUMIF(Ergebnisse_Roh!F$2:F$21,$B6,Punktematrix!$B$2:$B$21) -> 0 | G6: =SUMIF(Ergebnisse_Roh!G$2:G$21,$B6,Punktematrix!$B$2:$B$21) -> 0 | H6: =SUMIF(Ergebnisse_Roh!H$2:H$21,$B6,Punktematrix!$B$2:$B$21) -> 0 | I6: =SUMIF(Ergebnisse_Roh!I$2:I$21,$B6,Punktematrix!$B$2:$B$21) -> 0 | J6: =SUMIF(Ergebnisse_Roh!J$2:J$21,$B6,Punktematrix!$B$2:$B$21) -> 0 | ... W6: =SUMIF(Ergebnisse_Roh!W$2:W$21,$B6,Punktematrix!$B$2:$B$21) -> 2 | X6: =SUMIF(Ergebnisse_Roh!X$2:X$16,$B6,Punktematrix!$C$2:$C$16) -> 0 | Y6: =SUMIF(Ergebnisse_Roh!Y$2:Y$11,$B6,Punktematrix!$D$2:$D$11) -> 0 | Z6: =SUMIF(Ergebnisse_Roh!Z$2:Z$11,$B6,Punktematrix!$E$2:$E$11) -> 0 | AA6: =SUMIF(Ergebnisse_Roh!AA$2:AA$4,$B6,Punktematrix!$F$2:$F$4) -> 0 | AB6: =SUMIF(Ergebnisse_Roh!AB$2:AB$4,$B6,Punktematrix!$G$2:$G$4) -> 0
A7: Reto | B7: =Startlist2026!D34 -> CarapazRichardEF Education - EasyPost | C7: =SUMIF(Ergebnisse_Roh!C$2:C$21,$B7,Punktematrix!$B$2:$B$21) -> 0 | D7: =SUMIF(Ergebnisse_Roh!D$2:D$21,$B7,Punktematrix!$B$2:$B$21) -> 2 | E7: =SUMIF(Ergebnisse_Roh!E$2:E$21,$B7,Punktematrix!$B$2:$B$21) -> 15 | F7: =SUMIF(Ergebnisse_Roh!F$2:F$21,$B7,Punktematrix!$B$2:$B$21) -> 0 | G7: =SUMIF(Ergebnisse_Roh!G$2:G$21,$B7,Punktematrix!$B$2:$B$21) -> 0 | H7: =SUMIF(Ergebnisse_Roh!H$2:H$21,$B7,Punktematrix!$B$2:$B$21) -> 0 | I7: =SUMIF(Ergebnisse_Roh!I$2:I$21,$B7,Punktematrix!$B$2:$B$21) -> 0 | J7: =SUMIF(Ergebnisse_Roh!J$2:J$21,$B7,Punktematrix!$B$2:$B$21) -> 0 | ... W7: =SUMIF(Ergebnisse_Roh!W$2:W$21,$B7,Punktematrix!$B$2:$B$21) -> 2 | X7: =SUMIF(Ergebnisse_Roh!X$2:X$16,$B7,Punktematrix!$C$2:$C$16) -> 40 | Y7: =SUMIF(Ergebnisse_Roh!Y$2:Y$11,$B7,Punktematrix!$D$2:$D$11) -> 20 | Z7: =SUMIF(Ergebnisse_Roh!Z$2:Z$11,$B7,Punktematrix!$E$2:$E$11) -> 0 | AA7: =SUMIF(Ergebnisse_Roh!AA$2:AA$4,$B7,Punktematrix!$F$2:$F$4) -> 0 | AB7: =SUMIF(Ergebnisse_Roh!AB$2:AB$4,$B7,Punktematrix!$G$2:$G$4) -> 0
A8: Reto | B8: =Startlist2026!D42 -> SeixasPaulDecathlon CMA CGM Team | C8: =SUMIF(Ergebnisse_Roh!C$2:C$21,$B8,Punktematrix!$B$2:$B$21) -> 7 | D8: =SUMIF(Ergebnisse_Roh!D$2:D$21,$B8,Punktematrix!$B$2:$B$21) -> 8 | E8: =SUMIF(Ergebnisse_Roh!E$2:E$21,$B8,Punktematrix!$B$2:$B$21) -> 12 | F8: =SUMIF(Ergebnisse_Roh!F$2:F$21,$B8,Punktematrix!$B$2:$B$21) -> 0 | G8: =SUMIF(Ergebnisse_Roh!G$2:G$21,$B8,Punktematrix!$B$2:$B$21) -> 0 | H8: =SUMIF(Ergebnisse_Roh!H$2:H$21,$B8,Punktematrix!$B$2:$B$21) -> 11 | I8: =SUMIF(Ergebnisse_Roh!I$2:I$21,$B8,Punktematrix!$B$2:$B$21) -> 0 | J8: =SUMIF(Ergebnisse_Roh!J$2:J$21,$B8,Punktematrix!$B$2:$B$21) -> 0 | ... W8: =SUMIF(Ergebnisse_Roh!W$2:W$21,$B8,Punktematrix!$B$2:$B$21) -> 0 | X8: =SUMIF(Ergebnisse_Roh!X$2:X$16,$B8,Punktematrix!$C$2:$C$16) -> 60 | Y8: =SUMIF(Ergebnisse_Roh!Y$2:Y$11,$B8,Punktematrix!$D$2:$D$11) -> 6 | Z8: =SUMIF(Ergebnisse_Roh!Z$2:Z$11,$B8,Punktematrix!$E$2:$E$11) -> 0 | AA8: =SUMIF(Ergebnisse_Roh!AA$2:AA$4,$B8,Punktematrix!$F$2:$F$4) -> 10 | AB8: =SUMIF(Ergebnisse_Roh!AB$2:AB$4,$B8,Punktematrix!$G$2:$G$4) -> 0
A9: Reto | B9: =Startlist2026!D53 -> KanterMaxXDS Astana Team | C9: =SUMIF(Ergebnisse_Roh!C$2:C$21,$B9,Punktematrix!$B$2:$B$21) -> 0 | D9: =SUMIF(Ergebnisse_Roh!D$2:D$21,$B9,Punktematrix!$B$2:$B$21) -> 0 | E9: =SUMIF(Ergebnisse_Roh!E$2:E$21,$B9,Punktematrix!$B$2:$B$21) -> 0 | F9: =SUMIF(Ergebnisse_Roh!F$2:F$21,$B9,Punktematrix!$B$2:$B$21) -> 0 | G9: =SUMIF(Ergebnisse_Roh!G$2:G$21,$B9,Punktematrix!$B$2:$B$21) -> 20 | H9: =SUMIF(Ergebnisse_Roh!H$2:H$21,$B9,Punktematrix!$B$2:$B$21) -> 0 | I9: =SUMIF(Ergebnisse_Roh!I$2:I$21,$B9,Punktematrix!$B$2:$B$21) -> 12 | J9: =SUMIF(Ergebnisse_Roh!J$2:J$21,$B9,Punktematrix!$B$2:$B$21) -> 7 | ... W9: =SUMIF(Ergebnisse_Roh!W$2:W$21,$B9,Punktematrix!$B$2:$B$21) -> 12 | X9: =SUMIF(Ergebnisse_Roh!X$2:X$16,$B9,Punktematrix!$C$2:$C$16) -> 0 | Y9: =SUMIF(Ergebnisse_Roh!Y$2:Y$11,$B9,Punktematrix!$D$2:$D$11) -> 0 | Z9: =SUMIF(Ergebnisse_Roh!Z$2:Z$11,$B9,Punktematrix!$E$2:$E$11) -> 14 | AA9: =SUMIF(Ergebnisse_Roh!AA$2:AA$4,$B9,Punktematrix!$F$2:$F$4) -> 0 | AB9: =SUMIF(Ergebnisse_Roh!AB$2:AB$4,$B9,Punktematrix!$G$2:$G$4) -> 0
A10: Reto | B10: =Startlist2026!D86 -> PhilipsenJasperAlpecin - Premier Tech | C10: =SUMIF(Ergebnisse_Roh!C$2:C$21,$B10,Punktematrix!$B$2:$B$21) -> 0 | D10: =SUMIF(Ergebnisse_Roh!D$2:D$21,$B10,Punktematrix!$B$2:$B$21) -> 0 | E10: =SUMIF(Ergebnisse_Roh!E$2:E$21,$B10,Punktematrix!$B$2:$B$21) -> 0 | F10: =SUMIF(Ergebnisse_Roh!F$2:F$21,$B10,Punktematrix!$B$2:$B$21) -> 0 | G10: =SUMIF(Ergebnisse_Roh!G$2:G$21,$B10,Punktematrix!$B$2:$B$21) -> 11 | H10: =SUMIF(Ergebnisse_Roh!H$2:H$21,$B10,Punktematrix!$B$2:$B$21) -> 0 | I10: =SUMIF(Ergebnisse_Roh!I$2:I$21,$B10,Punktematrix!$B$2:$B$21) -> 11 | J10: =SUMIF(Ergebnisse_Roh!J$2:J$21,$B10,Punktematrix!$B$2:$B$21) -> 12 | ... W10: =SUMIF(Ergebnisse_Roh!W$2:W$21,$B10,Punktematrix!$B$2:$B$21) -> 20 | X10: =SUMIF(Ergebnisse_Roh!X$2:X$16,$B10,Punktematrix!$C$2:$C$16) -> 0 | Y10: =SUMIF(Ergebnisse_Roh!Y$2:Y$11,$B10,Punktematrix!$D$2:$D$11) -> 0 | Z10: =SUMIF(Ergebnisse_Roh!Z$2:Z$11,$B10,Punktematrix!$E$2:$E$11) -> 18 | AA10: =SUMIF(Ergebnisse_Roh!AA$2:AA$4,$B10,Punktematrix!$F$2:$F$4) -> 0 | AB10: =SUMIF(Ergebnisse_Roh!AB$2:AB$4,$B10,Punktematrix!$G$2:$G$4) -> 0
A11: Reto | B11: =Startlist2026!D74 -> MerlierTimSoudal Quick-Step | C11: =SUMIF(Ergebnisse_Roh!C$2:C$21,$B11,Punktematrix!$B$2:$B$21) -> 0 | D11: =SUMIF(Ergebnisse_Roh!D$2:D$21,$B11,Punktematrix!$B$2:$B$21) -> 0 | E11: =SUMIF(Ergebnisse_Roh!E$2:E$21,$B11,Punktematrix!$B$2:$B$21) -> 0 | F11: =SUMIF(Ergebnisse_Roh!F$2:F$21,$B11,Punktematrix!$B$2:$B$21) -> 0 | G11: =SUMIF(Ergebnisse_Roh!G$2:G$21,$B11,Punktematrix!$B$2:$B$21) -> 15 | H11: =SUMIF(Ergebnisse_Roh!H$2:H$21,$B11,Punktematrix!$B$2:$B$21) -> 0 | I11: =SUMIF(Ergebnisse_Roh!I$2:I$21,$B11,Punktematrix!$B$2:$B$21) -> 25 | J11: =SUMIF(Ergebnisse_Roh!J$2:J$21,$B11,Punktematrix!$B$2:$B$21) -> 25 | ... W11: =SUMIF(Ergebnisse_Roh!W$2:W$21,$B11,Punktematrix!$B$2:$B$21) -> 0 | X11: =SUMIF(Ergebnisse_Roh!X$2:X$16,$B11,Punktematrix!$C$2:$C$16) -> 0 | Y11: =SUMIF(Ergebnisse_Roh!Y$2:Y$11,$B11,Punktematrix!$D$2:$D$11) -> 0 | Z11: =SUMIF(Ergebnisse_Roh!Z$2:Z$11,$B11,Punktematrix!$E$2:$E$11) -> 0 | AA11: =SUMIF(Ergebnisse_Roh!AA$2:AA$4,$B11,Punktematrix!$F$2:$F$4) -> 0 | AB11: =SUMIF(Ergebnisse_Roh!AB$2:AB$4,$B11,Punktematrix!$G$2:$G$4) -> 0
A12: Reto | B12: =Startlist2026!D30 -> SkjelmoseMattiasLidl - Trek | C12: =SUMIF(Ergebnisse_Roh!C$2:C$21,$B12,Punktematrix!$B$2:$B$21) -> 0 | D12: =SUMIF(Ergebnisse_Roh!D$2:D$21,$B12,Punktematrix!$B$2:$B$21) -> 11 | E12: =SUMIF(Ergebnisse_Roh!E$2:E$21,$B12,Punktematrix!$B$2:$B$21) -> 5 | F12: =SUMIF(Ergebnisse_Roh!F$2:F$21,$B12,Punktematrix!$B$2:$B$21) -> 0 | G12: =SUMIF(Ergebnisse_Roh!G$2:G$21,$B12,Punktematrix!$B$2:$B$21) -> 0 | H12: =SUMIF(Ergebnisse_Roh!H$2:H$21,$B12,Punktematrix!$B$2:$B$21) -> 8 | I12: =SUMIF(Ergebnisse_Roh!I$2:I$21,$B12,Punktematrix!$B$2:$B$21) -> 0 | J12: =SUMIF(Ergebnisse_Roh!J$2:J$21,$B12,Punktematrix!$B$2:$B$21) -> 0 | ... W12: =SUMIF(Ergebnisse_Roh!W$2:W$21,$B12,Punktematrix!$B$2:$B$21) -> 0 | X12: =SUMIF(Ergebnisse_Roh!X$2:X$16,$B12,Punktematrix!$C$2:$C$16) -> 50 | Y12: =SUMIF(Ergebnisse_Roh!Y$2:Y$11,$B12,Punktematrix!$D$2:$D$11) -> 0 | Z12: =SUMIF(Ergebnisse_Roh!Z$2:Z$11,$B12,Punktematrix!$E$2:$E$11) -> 0 | AA12: =SUMIF(Ergebnisse_Roh!AA$2:AA$4,$B12,Punktematrix!$F$2:$F$4) -> 0 | AB12: =SUMIF(Ergebnisse_Roh!AB$2:AB$4,$B12,Punktematrix!$G$2:$G$4) -> 0
A13: Reto | B13: =Startlist2026!E18 -> Red Bull - BORA - hansgrohe | C13: =SUMIF(Ergebnisse_Roh!C$2:C$21,$B13,Punktematrix!$B$2:$B$21) -> 0 | D13: =SUMIF(Ergebnisse_Roh!D$2:D$21,$B13,Punktematrix!$B$2:$B$21) -> 0 | E13: =SUMIF(Ergebnisse_Roh!E$2:E$21,$B13,Punktematrix!$B$2:$B$21) -> 0 | F13: =SUMIF(Ergebnisse_Roh!F$2:F$21,$B13,Punktematrix!$B$2:$B$21) -> 0 | G13: =SUMIF(Ergebnisse_Roh!G$2:G$21,$B13,Punktematrix!$B$2:$B$21) -> 0 | H13: =SUMIF(Ergebnisse_Roh!H$2:H$21,$B13,Punktematrix!$B$2:$B$21) -> 0 | I13: =SUMIF(Ergebnisse_Roh!I$2:I$21,$B13,Punktematrix!$B$2:$B$21) -> 0 | J13: =SUMIF(Ergebnisse_Roh!J$2:J$21,$B13,Punktematrix!$B$2:$B$21) -> 0 | ... W13: =SUMIF(Ergebnisse_Roh!W$2:W$21,$B13,Punktematrix!$B$2:$B$21) -> 0 | X13: =SUMIF(Ergebnisse_Roh!X$2:X$16,$B13,Punktematrix!$C$2:$C$16) -> 0 | Y13: =SUMIF(Ergebnisse_Roh!Y$2:Y$11,$B13,Punktematrix!$D$2:$D$11) -> 0 | Z13: =SUMIF(Ergebnisse_Roh!Z$2:Z$11,$B13,Punktematrix!$E$2:$E$11) -> 0 | AA13: =SUMIF(Ergebnisse_Roh!AA$2:AA$4,$B13,Punktematrix!$F$2:$F$4) -> 0 | AB13: =SUMIF(Ergebnisse_Roh!AB$2:AB$4,$B13,Punktematrix!$G$2:$G$4) -> 20
A14: Nora | B14: =Startlist2026!D2 -> PogačarTadejUAE Team Emirates - XRG | C14: =SUMIF(Ergebnisse_Roh!C$2:C$21,$B14,Punktematrix!$B$2:$B$21) -> 17 | D14: =SUMIF(Ergebnisse_Roh!D$2:D$21,$B14,Punktematrix!$B$2:$B$21) -> 20 | E14: =SUMIF(Ergebnisse_Roh!E$2:E$21,$B14,Punktematrix!$B$2:$B$21) -> 30 | F14: =SUMIF(Ergebnisse_Roh!F$2:F$21,$B14,Punktematrix!$B$2:$B$21) -> 0 | G14: =SUMIF(Ergebnisse_Roh!G$2:G$21,$B14,Punktematrix!$B$2:$B$21) -> 0 | H14: =SUMIF(Ergebnisse_Roh!H$2:H$21,$B14,Punktematrix!$B$2:$B$21) -> 30 | I14: =SUMIF(Ergebnisse_Roh!I$2:I$21,$B14,Punktematrix!$B$2:$B$21) -> 5 | J14: =SUMIF(Ergebnisse_Roh!J$2:J$21,$B14,Punktematrix!$B$2:$B$21) -> 5 | ... W14: =SUMIF(Ergebnisse_Roh!W$2:W$21,$B14,Punktematrix!$B$2:$B$21) -> 3 | X14: =SUMIF(Ergebnisse_Roh!X$2:X$16,$B14,Punktematrix!$C$2:$C$16) -> 75 | Y14: =SUMIF(Ergebnisse_Roh!Y$2:Y$11,$B14,Punktematrix!$D$2:$D$11) -> 18 | Z14: =SUMIF(Ergebnisse_Roh!Z$2:Z$11,$B14,Punktematrix!$E$2:$E$11) -> 8 | AA14: =SUMIF(Ergebnisse_Roh!AA$2:AA$4,$B14,Punktematrix!$F$2:$F$4) -> 0 | AB14: =SUMIF(Ergebnisse_Roh!AB$2:AB$4,$B14,Punktematrix!$G$2:$G$4) -> 0
A15: Nora | B15: =Startlist2026!D82 -> van der PoelMathieuAlpecin - Premier Tech | C15: =SUMIF(Ergebnisse_Roh!C$2:C$21,$B15,Punktematrix!$B$2:$B$21) -> 5 | D15: =SUMIF(Ergebnisse_Roh!D$2:D$21,$B15,Punktematrix!$B$2:$B$21) -> 0 | E15: =SUMIF(Ergebnisse_Roh!E$2:E$21,$B15,Punktematrix!$B$2:$B$21) -> 0 | F15: =SUMIF(Ergebnisse_Roh!F$2:F$21,$B15,Punktematrix!$B$2:$B$21) -> 0 | G15: =SUMIF(Ergebnisse_Roh!G$2:G$21,$B15,Punktematrix!$B$2:$B$21) -> 0 | H15: =SUMIF(Ergebnisse_Roh!H$2:H$21,$B15,Punktematrix!$B$2:$B$21) -> 0 | I15: =SUMIF(Ergebnisse_Roh!I$2:I$21,$B15,Punktematrix!$B$2:$B$21) -> 0 | J15: =SUMIF(Ergebnisse_Roh!J$2:J$21,$B15,Punktematrix!$B$2:$B$21) -> 1 | ... W15: =SUMIF(Ergebnisse_Roh!W$2:W$21,$B15,Punktematrix!$B$2:$B$21) -> 25 | X15: =SUMIF(Ergebnisse_Roh!X$2:X$16,$B15,Punktematrix!$C$2:$C$16) -> 0 | Y15: =SUMIF(Ergebnisse_Roh!Y$2:Y$11,$B15,Punktematrix!$D$2:$D$11) -> 0 | Z15: =SUMIF(Ergebnisse_Roh!Z$2:Z$11,$B15,Punktematrix!$E$2:$E$11) -> 0 | AA15: =SUMIF(Ergebnisse_Roh!AA$2:AA$4,$B15,Punktematrix!$F$2:$F$4) -> 0 | AB15: =SUMIF(Ergebnisse_Roh!AB$2:AB$4,$B15,Punktematrix!$G$2:$G$4) -> 0
A16: Nora | B16: =Startlist2026!D86 -> PhilipsenJasperAlpecin - Premier Tech | C16: =SUMIF(Ergebnisse_Roh!C$2:C$21,$B16,Punktematrix!$B$2:$B$21) -> 0 | D16: =SUMIF(Ergebnisse_Roh!D$2:D$21,$B16,Punktematrix!$B$2:$B$21) -> 0 | E16: =SUMIF(Ergebnisse_Roh!E$2:E$21,$B16,Punktematrix!$B$2:$B$21) -> 0 | F16: =SUMIF(Ergebnisse_Roh!F$2:F$21,$B16,Punktematrix!$B$2:$B$21) -> 0 | G16: =SUMIF(Ergebnisse_Roh!G$2:G$21,$B16,Punktematrix!$B$2:$B$21) -> 11 | H16: =SUMIF(Ergebnisse_Roh!H$2:H$21,$B16,Punktematrix!$B$2:$B$21) -> 0 | I16: =SUMIF(Ergebnisse_Roh!I$2:I$21,$B16,Punktematrix!$B$2:$B$21) -> 11 | J16: =SUMIF(Ergebnisse_Roh!J$2:J$21,$B16,Punktematrix!$B$2:$B$21) -> 12 | ... W16: =SUMIF(Ergebnisse_Roh!W$2:W$21,$B16,Punktematrix!$B$2:$B$21) -> 20 | X16: =SUMIF(Ergebnisse_Roh!X$2:X$16,$B16,Punktematrix!$C$2:$C$16) -> 0 | Y16: =SUMIF(Ergebnisse_Roh!Y$2:Y$11,$B16,Punktematrix!$D$2:$D$11) -> 0 | Z16: =SUMIF(Ergebnisse_Roh!Z$2:Z$11,$B16,Punktematrix!$E$2:$E$11) -> 18 | AA16: =SUMIF(Ergebnisse_Roh!AA$2:AA$4,$B16,Punktematrix!$F$2:$F$4) -> 0 | AB16: =SUMIF(Ergebnisse_Roh!AB$2:AB$4,$B16,Punktematrix!$G$2:$G$4) -> 0
A17: Nora | B17: =Startlist2026!D42 -> SeixasPaulDecathlon CMA CGM Team | C17: =SUMIF(Ergebnisse_Roh!C$2:C$21,$B17,Punktematrix!$B$2:$B$21) -> 7 | D17: =SUMIF(Ergebnisse_Roh!D$2:D$21,$B17,Punktematrix!$B$2:$B$21) -> 8 | E17: =SUMIF(Ergebnisse_Roh!E$2:E$21,$B17,Punktematrix!$B$2:$B$21) -> 12 | F17: =SUMIF(Ergebnisse_Roh!F$2:F$21,$B17,Punktematrix!$B$2:$B$21) -> 0 | G17: =SUMIF(Ergebnisse_Roh!G$2:G$21,$B17,Punktematrix!$B$2:$B$21) -> 0 | H17: =SUMIF(Ergebnisse_Roh!H$2:H$21,$B17,Punktematrix!$B$2:$B$21) -> 11 | I17: =SUMIF(Ergebnisse_Roh!I$2:I$21,$B17,Punktematrix!$B$2:$B$21) -> 0 | J17: =SUMIF(Ergebnisse_Roh!J$2:J$21,$B17,Punktematrix!$B$2:$B$21) -> 0 | ... W17: =SUMIF(Ergebnisse_Roh!W$2:W$21,$B17,Punktematrix!$B$2:$B$21) -> 0 | X17: =SUMIF(Ergebnisse_Roh!X$2:X$16,$B17,Punktematrix!$C$2:$C$16) -> 60 | Y17: =SUMIF(Ergebnisse_Roh!Y$2:Y$11,$B17,Punktematrix!$D$2:$D$11) -> 6 | Z17: =SUMIF(Ergebnisse_Roh!Z$2:Z$11,$B17,Punktematrix!$E$2:$E$11) -> 0 | AA17: =SUMIF(Ergebnisse_Roh!AA$2:AA$4,$B17,Punktematrix!$F$2:$F$4) -> 10 | AB17: =SUMIF(Ergebnisse_Roh!AB$2:AB$4,$B17,Punktematrix!$G$2:$G$4) -> 0
A18: Nora | B18: =Startlist2026!E2 -> UAE Team Emirates - XRG | C18: =SUMIF(Ergebnisse_Roh!C$2:C$21,$B18,Punktematrix!$B$2:$B$21) -> 0 | D18: =SUMIF(Ergebnisse_Roh!D$2:D$21,$B18,Punktematrix!$B$2:$B$21) -> 2 | E18: =SUMIF(Ergebnisse_Roh!E$2:E$21,$B18,Punktematrix!$B$2:$B$21) -> 2 | F18: =SUMIF(Ergebnisse_Roh!F$2:F$21,$B18,Punktematrix!$B$2:$B$21) -> 0 | G18: =SUMIF(Ergebnisse_Roh!G$2:G$21,$B18,Punktematrix!$B$2:$B$21) -> 0 | H18: =SUMIF(Ergebnisse_Roh!H$2:H$21,$B18,Punktematrix!$B$2:$B$21) -> 2 | I18: =SUMIF(Ergebnisse_Roh!I$2:I$21,$B18,Punktematrix!$B$2:$B$21) -> 0 | J18: =SUMIF(Ergebnisse_Roh!J$2:J$21,$B18,Punktematrix!$B$2:$B$21) -> 0 | ... W18: =SUMIF(Ergebnisse_Roh!W$2:W$21,$B18,Punktematrix!$B$2:$B$21) -> 0 | X18: =SUMIF(Ergebnisse_Roh!X$2:X$16,$B18,Punktematrix!$C$2:$C$16) -> 0 | Y18: =SUMIF(Ergebnisse_Roh!Y$2:Y$11,$B18,Punktematrix!$D$2:$D$11) -> 0 | Z18: =SUMIF(Ergebnisse_Roh!Z$2:Z$11,$B18,Punktematrix!$E$2:$E$11) -> 0 | AA18: =SUMIF(Ergebnisse_Roh!AA$2:AA$4,$B18,Punktematrix!$F$2:$F$4) -> 0 | AB18: =SUMIF(Ergebnisse_Roh!AB$2:AB$4,$B18,Punktematrix!$G$2:$G$4) -> 25
A19: Nora | B19: =Startlist2026!D9 -> YatesAdamUAE Team Emirates - XRG | C19: =SUMIF(Ergebnisse_Roh!C$2:C$21,$B19,Punktematrix!$B$2:$B$21) -> 0 | D19: =SUMIF(Ergebnisse_Roh!D$2:D$21,$B19,Punktematrix!$B$2:$B$21) -> 0 | E19: =SUMIF(Ergebnisse_Roh!E$2:E$21,$B19,Punktematrix!$B$2:$B$21) -> 0 | F19: =SUMIF(Ergebnisse_Roh!F$2:F$21,$B19,Punktematrix!$B$2:$B$21) -> 0 | G19: =SUMIF(Ergebnisse_Roh!G$2:G$21,$B19,Punktematrix!$B$2:$B$21) -> 0 | H19: =SUMIF(Ergebnisse_Roh!H$2:H$21,$B19,Punktematrix!$B$2:$B$21) -> 0 | I19: =SUMIF(Ergebnisse_Roh!I$2:I$21,$B19,Punktematrix!$B$2:$B$21) -> 0 | J19: =SUMIF(Ergebnisse_Roh!J$2:J$21,$B19,Punktematrix!$B$2:$B$21) -> 0 | ... W19: =SUMIF(Ergebnisse_Roh!W$2:W$21,$B19,Punktematrix!$B$2:$B$21) -> 0 | X19: =SUMIF(Ergebnisse_Roh!X$2:X$16,$B19,Punktematrix!$C$2:$C$16) -> 0 | Y19: =SUMIF(Ergebnisse_Roh!Y$2:Y$11,$B19,Punktematrix!$D$2:$D$11) -> 0 | Z19: =SUMIF(Ergebnisse_Roh!Z$2:Z$11,$B19,Punktematrix!$E$2:$E$11) -> 0 | AA19: =SUMIF(Ergebnisse_Roh!AA$2:AA$4,$B19,Punktematrix!$F$2:$F$4) -> 0 | AB19: =SUMIF(Ergebnisse_Roh!AB$2:AB$4,$B19,Punktematrix!$G$2:$G$4) -> 0
A20: Nora | B20: =Startlist2026!D122 -> De LieArnaudLotto Intermarché | C20: =SUMIF(Ergebnisse_Roh!C$2:C$21,$B20,Punktematrix!$B$2:$B$21) -> 0 | D20: =SUMIF(Ergebnisse_Roh!D$2:D$21,$B20,Punktematrix!$B$2:$B$21) -> 0 | E20: =SUMIF(Ergebnisse_Roh!E$2:E$21,$B20,Punktematrix!$B$2:$B$21) -> 0 | F20: =SUMIF(Ergebnisse_Roh!F$2:F$21,$B20,Punktematrix!$B$2:$B$21) -> 0 | G20: =SUMIF(Ergebnisse_Roh!G$2:G$21,$B20,Punktematrix!$B$2:$B$21) -> 0 | H20: =SUMIF(Ergebnisse_Roh!H$2:H$21,$B20,Punktematrix!$B$2:$B$21) -> 0 | I20: =SUMIF(Ergebnisse_Roh!I$2:I$21,$B20,Punktematrix!$B$2:$B$21) -> 0 | J20: =SUMIF(Ergebnisse_Roh!J$2:J$21,$B20,Punktematrix!$B$2:$B$21) -> 0 | ... W20: =SUMIF(Ergebnisse_Roh!W$2:W$21,$B20,Punktematrix!$B$2:$B$21) -> 0 | X20: =SUMIF(Ergebnisse_Roh!X$2:X$16,$B20,Punktematrix!$C$2:$C$16) -> 0 | Y20: =SUMIF(Ergebnisse_Roh!Y$2:Y$11,$B20,Punktematrix!$D$2:$D$11) -> 0 | Z20: =SUMIF(Ergebnisse_Roh!Z$2:Z$11,$B20,Punktematrix!$E$2:$E$11) -> 0 | AA20: =SUMIF(Ergebnisse_Roh!AA$2:AA$4,$B20,Punktematrix!$F$2:$F$4) -> 0 | AB20: =SUMIF(Ergebnisse_Roh!AB$2:AB$4,$B20,Punktematrix!$G$2:$G$4) -> 0
A21: Nora | B21: =Startlist2026!D13 -> CampenaertsVictorTeam Visma | Lease a Bike | C21: =SUMIF(Ergebnisse_Roh!C$2:C$21,$B21,Punktematrix!$B$2:$B$21) -> 0 | D21: =SUMIF(Ergebnisse_Roh!D$2:D$21,$B21,Punktematrix!$B$2:$B$21) -> 0 | E21: =SUMIF(Ergebnisse_Roh!E$2:E$21,$B21,Punktematrix!$B$2:$B$21) -> 0 | F21: =SUMIF(Ergebnisse_Roh!F$2:F$21,$B21,Punktematrix!$B$2:$B$21) -> 0 | G21: =SUMIF(Ergebnisse_Roh!G$2:G$21,$B21,Punktematrix!$B$2:$B$21) -> 0 | H21: =SUMIF(Ergebnisse_Roh!H$2:H$21,$B21,Punktematrix!$B$2:$B$21) -> 0 | I21: =SUMIF(Ergebnisse_Roh!I$2:I$21,$B21,Punktematrix!$B$2:$B$21) -> 0 | J21: =SUMIF(Ergebnisse_Roh!J$2:J$21,$B21,Punktematrix!$B$2:$B$21) -> 0 | ... W21: =SUMIF(Ergebnisse_Roh!W$2:W$21,$B21,Punktematrix!$B$2:$B$21) -> 0 | X21: =SUMIF(Ergebnisse_Roh!X$2:X$16,$B21,Punktematrix!$C$2:$C$16) -> 0 | Y21: =SUMIF(Ergebnisse_Roh!Y$2:Y$11,$B21,Punktematrix!$D$2:$D$11) -> 0 | Z21: =SUMIF(Ergebnisse_Roh!Z$2:Z$11,$B21,Punktematrix!$E$2:$E$11) -> 0 | AA21: =SUMIF(Ergebnisse_Roh!AA$2:AA$4,$B21,Punktematrix!$F$2:$F$4) -> 0 | AB21: =SUMIF(Ergebnisse_Roh!AB$2:AB$4,$B21,Punktematrix!$G$2:$G$4) -> 0
A22: Nora | B22: =Startlist2026!D10 -> VingegaardJonasTeam Visma | Lease a Bike | C22: =SUMIF(Ergebnisse_Roh!C$2:C$21,$B22,Punktematrix!$B$2:$B$21) -> 28 | D22: =SUMIF(Ergebnisse_Roh!D$2:D$21,$B22,Punktematrix!$B$2:$B$21) -> 15 | E22: =SUMIF(Ergebnisse_Roh!E$2:E$21,$B22,Punktematrix!$B$2:$B$21) -> 20 | F22: =SUMIF(Ergebnisse_Roh!F$2:F$21,$B22,Punktematrix!$B$2:$B$21) -> 0 | G22: =SUMIF(Ergebnisse_Roh!G$2:G$21,$B22,Punktematrix!$B$2:$B$21) -> 0 | H22: =SUMIF(Ergebnisse_Roh!H$2:H$21,$B22,Punktematrix!$B$2:$B$21) -> 20 | I22: =SUMIF(Ergebnisse_Roh!I$2:I$21,$B22,Punktematrix!$B$2:$B$21) -> 0 | J22: =SUMIF(Ergebnisse_Roh!J$2:J$21,$B22,Punktematrix!$B$2:$B$21) -> 0 | ... W22: =SUMIF(Ergebnisse_Roh!W$2:W$21,$B22,Punktematrix!$B$2:$B$21) -> 0 | X22: =SUMIF(Ergebnisse_Roh!X$2:X$16,$B22,Punktematrix!$C$2:$C$16) -> 0 | Y22: =SUMIF(Ergebnisse_Roh!Y$2:Y$11,$B22,Punktematrix!$D$2:$D$11) -> 0 | Z22: =SUMIF(Ergebnisse_Roh!Z$2:Z$11,$B22,Punktematrix!$E$2:$E$11) -> 0 | AA22: =SUMIF(Ergebnisse_Roh!AA$2:AA$4,$B22,Punktematrix!$F$2:$F$4) -> 0 | AB22: =SUMIF(Ergebnisse_Roh!AB$2:AB$4,$B22,Punktematrix!$G$2:$G$4) -> 0
A23: Nora | B23: =Startlist2026!D67 -> ArensmanThymenNetcompany INEOS | C23: =SUMIF(Ergebnisse_Roh!C$2:C$21,$B23,Punktematrix!$B$2:$B$21) -> 0 | D23: =SUMIF(Ergebnisse_Roh!D$2:D$21,$B23,Punktematrix!$B$2:$B$21) -> 0 | E23: =SUMIF(Ergebnisse_Roh!E$2:E$21,$B23,Punktematrix!$B$2:$B$21) -> 0 | F23: =SUMIF(Ergebnisse_Roh!F$2:F$21,$B23,Punktematrix!$B$2:$B$21) -> 0 | G23: =SUMIF(Ergebnisse_Roh!G$2:G$21,$B23,Punktematrix!$B$2:$B$21) -> 0 | H23: =SUMIF(Ergebnisse_Roh!H$2:H$21,$B23,Punktematrix!$B$2:$B$21) -> 0 | I23: =SUMIF(Ergebnisse_Roh!I$2:I$21,$B23,Punktematrix!$B$2:$B$21) -> 0 | J23: =SUMIF(Ergebnisse_Roh!J$2:J$21,$B23,Punktematrix!$B$2:$B$21) -> 0 | ... W23: =SUMIF(Ergebnisse_Roh!W$2:W$21,$B23,Punktematrix!$B$2:$B$21) -> 0 | X23: =SUMIF(Ergebnisse_Roh!X$2:X$16,$B23,Punktematrix!$C$2:$C$16) -> 0 | Y23: =SUMIF(Ergebnisse_Roh!Y$2:Y$11,$B23,Punktematrix!$D$2:$D$11) -> 0 | Z23: =SUMIF(Ergebnisse_Roh!Z$2:Z$11,$B23,Punktematrix!$E$2:$E$11) -> 0 | AA23: =SUMIF(Ergebnisse_Roh!AA$2:AA$4,$B23,Punktematrix!$F$2:$F$4) -> 0 | AB23: =SUMIF(Ergebnisse_Roh!AB$2:AB$4,$B23,Punktematrix!$G$2:$G$4) -> 0
A24: Chrysli | B24: =Startlist2026!D22 -> LipowitzFlorianRed Bull - BORA - hansgrohe | C24: =SUMIF(Ergebnisse_Roh!C$2:C$21,$B24,Punktematrix!$B$2:$B$21) -> 8 | D24: =SUMIF(Ergebnisse_Roh!D$2:D$21,$B24,Punktematrix!$B$2:$B$21) -> 0 | E24: =SUMIF(Ergebnisse_Roh!E$2:E$21,$B24,Punktematrix!$B$2:$B$21) -> 9 | F24: =SUMIF(Ergebnisse_Roh!F$2:F$21,$B24,Punktematrix!$B$2:$B$21) -> 0 | G24: =SUMIF(Ergebnisse_Roh!G$2:G$21,$B24,Punktematrix!$B$2:$B$21) -> 0 | H24: =SUMIF(Ergebnisse_Roh!H$2:H$21,$B24,Punktematrix!$B$2:$B$21) -> 10 | I24: =SUMIF(Ergebnisse_Roh!I$2:I$21,$B24,Punktematrix!$B$2:$B$21) -> 0 | J24: =SUMIF(Ergebnisse_Roh!J$2:J$21,$B24,Punktematrix!$B$2:$B$21) -> 0 | ... W24: =SUMIF(Ergebnisse_Roh!W$2:W$21,$B24,Punktematrix!$B$2:$B$21) -> 0 | X24: =SUMIF(Ergebnisse_Roh!X$2:X$16,$B24,Punktematrix!$C$2:$C$16) -> 0 | Y24: =SUMIF(Ergebnisse_Roh!Y$2:Y$11,$B24,Punktematrix!$D$2:$D$11) -> 0 | Z24: =SUMIF(Ergebnisse_Roh!Z$2:Z$11,$B24,Punktematrix!$E$2:$E$11) -> 0 | AA24: =SUMIF(Ergebnisse_Roh!AA$2:AA$4,$B24,Punktematrix!$F$2:$F$4) -> 0 | AB24: =SUMIF(Ergebnisse_Roh!AB$2:AB$4,$B24,Punktematrix!$G$2:$G$4) -> 0
A25: Chrysli | B25: =Startlist2026!D42 -> SeixasPaulDecathlon CMA CGM Team | C25: =SUMIF(Ergebnisse_Roh!C$2:C$21,$B25,Punktematrix!$B$2:$B$21) -> 7 | D25: =SUMIF(Ergebnisse_Roh!D$2:D$21,$B25,Punktematrix!$B$2:$B$21) -> 8 | E25: =SUMIF(Ergebnisse_Roh!E$2:E$21,$B25,Punktematrix!$B$2:$B$21) -> 12 | F25: =SUMIF(Ergebnisse_Roh!F$2:F$21,$B25,Punktematrix!$B$2:$B$21) -> 0 | G25: =SUMIF(Ergebnisse_Roh!G$2:G$21,$B25,Punktematrix!$B$2:$B$21) -> 0 | H25: =SUMIF(Ergebnisse_Roh!H$2:H$21,$B25,Punktematrix!$B$2:$B$21) -> 11 | I25: =SUMIF(Ergebnisse_Roh!I$2:I$21,$B25,Punktematrix!$B$2:$B$21) -> 0 | J25: =SUMIF(Ergebnisse_Roh!J$2:J$21,$B25,Punktematrix!$B$2:$B$21) -> 0 | ... W25: =SUMIF(Ergebnisse_Roh!W$2:W$21,$B25,Punktematrix!$B$2:$B$21) -> 0 | X25: =SUMIF(Ergebnisse_Roh!X$2:X$16,$B25,Punktematrix!$C$2:$C$16) -> 60 | Y25: =SUMIF(Ergebnisse_Roh!Y$2:Y$11,$B25,Punktematrix!$D$2:$D$11) -> 6 | Z25: =SUMIF(Ergebnisse_Roh!Z$2:Z$11,$B25,Punktematrix!$E$2:$E$11) -> 0 | AA25: =SUMIF(Ergebnisse_Roh!AA$2:AA$4,$B25,Punktematrix!$F$2:$F$4) -> 10 | AB25: =SUMIF(Ergebnisse_Roh!AB$2:AB$4,$B25,Punktematrix!$G$2:$G$4) -> 0
A26: Chrysli | B26: =Startlist2026!D5 -> McNultyBrandonUAE Team Emirates - XRG | C26: =SUMIF(Ergebnisse_Roh!C$2:C$21,$B26,Punktematrix!$B$2:$B$21) -> 0 | D26: =SUMIF(Ergebnisse_Roh!D$2:D$21,$B26,Punktematrix!$B$2:$B$21) -> 0 | E26: =SUMIF(Ergebnisse_Roh!E$2:E$21,$B26,Punktematrix!$B$2:$B$21) -> 0 | F26: =SUMIF(Ergebnisse_Roh!F$2:F$21,$B26,Punktematrix!$B$2:$B$21) -> 0 | G26: =SUMIF(Ergebnisse_Roh!G$2:G$21,$B26,Punktematrix!$B$2:$B$21) -> 0 | H26: =SUMIF(Ergebnisse_Roh!H$2:H$21,$B26,Punktematrix!$B$2:$B$21) -> 0 | I26: =SUMIF(Ergebnisse_Roh!I$2:I$21,$B26,Punktematrix!$B$2:$B$21) -> 0 | J26: =SUMIF(Ergebnisse_Roh!J$2:J$21,$B26,Punktematrix!$B$2:$B$21) -> 0 | ... W26: =SUMIF(Ergebnisse_Roh!W$2:W$21,$B26,Punktematrix!$B$2:$B$21) -> 0 | X26: =SUMIF(Ergebnisse_Roh!X$2:X$16,$B26,Punktematrix!$C$2:$C$16) -> 0 | Y26: =SUMIF(Ergebnisse_Roh!Y$2:Y$11,$B26,Punktematrix!$D$2:$D$11) -> 0 | Z26: =SUMIF(Ergebnisse_Roh!Z$2:Z$11,$B26,Punktematrix!$E$2:$E$11) -> 0 | AA26: =SUMIF(Ergebnisse_Roh!AA$2:AA$4,$B26,Punktematrix!$F$2:$F$4) -> 0 | AB26: =SUMIF(Ergebnisse_Roh!AB$2:AB$4,$B26,Punktematrix!$G$2:$G$4) -> 0
A27: Chrysli | B27: =Startlist2026!D24 -> van DijkeTimRed Bull - BORA - hansgrohe | C27: =SUMIF(Ergebnisse_Roh!C$2:C$21,$B27,Punktematrix!$B$2:$B$21) -> 0 | D27: =SUMIF(Ergebnisse_Roh!D$2:D$21,$B27,Punktematrix!$B$2:$B$21) -> 0 | E27: =SUMIF(Ergebnisse_Roh!E$2:E$21,$B27,Punktematrix!$B$2:$B$21) -> 0 | F27: =SUMIF(Ergebnisse_Roh!F$2:F$21,$B27,Punktematrix!$B$2:$B$21) -> 0 | G27: =SUMIF(Ergebnisse_Roh!G$2:G$21,$B27,Punktematrix!$B$2:$B$21) -> 0 | H27: =SUMIF(Ergebnisse_Roh!H$2:H$21,$B27,Punktematrix!$B$2:$B$21) -> 0 | I27: =SUMIF(Ergebnisse_Roh!I$2:I$21,$B27,Punktematrix!$B$2:$B$21) -> 0 | J27: =SUMIF(Ergebnisse_Roh!J$2:J$21,$B27,Punktematrix!$B$2:$B$21) -> 0 | ... W27: =SUMIF(Ergebnisse_Roh!W$2:W$21,$B27,Punktematrix!$B$2:$B$21) -> 0 | X27: =SUMIF(Ergebnisse_Roh!X$2:X$16,$B27,Punktematrix!$C$2:$C$16) -> 0 | Y27: =SUMIF(Ergebnisse_Roh!Y$2:Y$11,$B27,Punktematrix!$D$2:$D$11) -> 0 | Z27: =SUMIF(Ergebnisse_Roh!Z$2:Z$11,$B27,Punktematrix!$E$2:$E$11) -> 0 | AA27: =SUMIF(Ergebnisse_Roh!AA$2:AA$4,$B27,Punktematrix!$F$2:$F$4) -> 0 | AB27: =SUMIF(Ergebnisse_Roh!AB$2:AB$4,$B27,Punktematrix!$G$2:$G$4) -> 0
A28: Chrysli | B28: =Startlist2026!D114 -> UijtdebroeksCianMovistar Team | C28: =SUMIF(Ergebnisse_Roh!C$2:C$21,$B28,Punktematrix!$B$2:$B$21) -> 0 | D28: =SUMIF(Ergebnisse_Roh!D$2:D$21,$B28,Punktematrix!$B$2:$B$21) -> 0 | E28: =SUMIF(Ergebnisse_Roh!E$2:E$21,$B28,Punktematrix!$B$2:$B$21) -> 0 | F28: =SUMIF(Ergebnisse_Roh!F$2:F$21,$B28,Punktematrix!$B$2:$B$21) -> 0 | G28: =SUMIF(Ergebnisse_Roh!G$2:G$21,$B28,Punktematrix!$B$2:$B$21) -> 0 | H28: =SUMIF(Ergebnisse_Roh!H$2:H$21,$B28,Punktematrix!$B$2:$B$21) -> 0 | I28: =SUMIF(Ergebnisse_Roh!I$2:I$21,$B28,Punktematrix!$B$2:$B$21) -> 0 | J28: =SUMIF(Ergebnisse_Roh!J$2:J$21,$B28,Punktematrix!$B$2:$B$21) -> 0 | ... W28: =SUMIF(Ergebnisse_Roh!W$2:W$21,$B28,Punktematrix!$B$2:$B$21) -> 0 | X28: =SUMIF(Ergebnisse_Roh!X$2:X$16,$B28,Punktematrix!$C$2:$C$16) -> 0 | Y28: =SUMIF(Ergebnisse_Roh!Y$2:Y$11,$B28,Punktematrix!$D$2:$D$11) -> 0 | Z28: =SUMIF(Ergebnisse_Roh!Z$2:Z$11,$B28,Punktematrix!$E$2:$E$11) -> 0 | AA28: =SUMIF(Ergebnisse_Roh!AA$2:AA$4,$B28,Punktematrix!$F$2:$F$4) -> 0 | AB28: =SUMIF(Ergebnisse_Roh!AB$2:AB$4,$B28,Punktematrix!$G$2:$G$4) -> 0
A29: Chrysli | B29: =Startlist2026!D83 -> DebruyneRamsesAlpecin - Premier Tech | C29: =SUMIF(Ergebnisse_Roh!C$2:C$21,$B29,Punktematrix!$B$2:$B$21) -> 0 | D29: =SUMIF(Ergebnisse_Roh!D$2:D$21,$B29,Punktematrix!$B$2:$B$21) -> 0 | E29: =SUMIF(Ergebnisse_Roh!E$2:E$21,$B29,Punktematrix!$B$2:$B$21) -> 0 | F29: =SUMIF(Ergebnisse_Roh!F$2:F$21,$B29,Punktematrix!$B$2:$B$21) -> 11 | G29: =SUMIF(Ergebnisse_Roh!G$2:G$21,$B29,Punktematrix!$B$2:$B$21) -> 0 | H29: =SUMIF(Ergebnisse_Roh!H$2:H$21,$B29,Punktematrix!$B$2:$B$21) -> 0 | I29: =SUMIF(Ergebnisse_Roh!I$2:I$21,$B29,Punktematrix!$B$2:$B$21) -> 0 | J29: =SUMIF(Ergebnisse_Roh!J$2:J$21,$B29,Punktematrix!$B$2:$B$21) -> 0 | ... W29: =SUMIF(Ergebnisse_Roh!W$2:W$21,$B29,Punktematrix!$B$2:$B$21) -> 0 | X29: =SUMIF(Ergebnisse_Roh!X$2:X$16,$B29,Punktematrix!$C$2:$C$16) -> 0 | Y29: =SUMIF(Ergebnisse_Roh!Y$2:Y$11,$B29,Punktematrix!$D$2:$D$11) -> 0 | Z29: =SUMIF(Ergebnisse_Roh!Z$2:Z$11,$B29,Punktematrix!$E$2:$E$11) -> 0 | AA29: =SUMIF(Ergebnisse_Roh!AA$2:AA$4,$B29,Punktematrix!$F$2:$F$4) -> 0 | AB29: =SUMIF(Ergebnisse_Roh!AB$2:AB$4,$B29,Punktematrix!$G$2:$G$4) -> 0
A30: Chrysli | B30: =Startlist2026!D3 -> del ToroIsaacUAE Team Emirates - XRG | C30: =SUMIF(Ergebnisse_Roh!C$2:C$21,$B30,Punktematrix!$B$2:$B$21) -> 10 | D30: =SUMIF(Ergebnisse_Roh!D$2:D$21,$B30,Punktematrix!$B$2:$B$21) -> 29 | E30: =SUMIF(Ergebnisse_Roh!E$2:E$21,$B30,Punktematrix!$B$2:$B$21) -> 10 | F30: =SUMIF(Ergebnisse_Roh!F$2:F$21,$B30,Punktematrix!$B$2:$B$21) -> 0 | G30: =SUMIF(Ergebnisse_Roh!G$2:G$21,$B30,Punktematrix!$B$2:$B$21) -> 0 | H30: =SUMIF(Ergebnisse_Roh!H$2:H$21,$B30,Punktematrix!$B$2:$B$21) -> 17 | I30: =SUMIF(Ergebnisse_Roh!I$2:I$21,$B30,Punktematrix!$B$2:$B$21) -> 2 | J30: =SUMIF(Ergebnisse_Roh!J$2:J$21,$B30,Punktematrix!$B$2:$B$21) -> 2 | ... W30: =SUMIF(Ergebnisse_Roh!W$2:W$21,$B30,Punktematrix!$B$2:$B$21) -> 2 | X30: =SUMIF(Ergebnisse_Roh!X$2:X$16,$B30,Punktematrix!$C$2:$C$16) -> 65 | Y30: =SUMIF(Ergebnisse_Roh!Y$2:Y$11,$B30,Punktematrix!$D$2:$D$11) -> 10 | Z30: =SUMIF(Ergebnisse_Roh!Z$2:Z$11,$B30,Punktematrix!$E$2:$E$11) -> 4 | AA30: =SUMIF(Ergebnisse_Roh!AA$2:AA$4,$B30,Punktematrix!$F$2:$F$4) -> 15 | AB30: =SUMIF(Ergebnisse_Roh!AB$2:AB$4,$B30,Punktematrix!$G$2:$G$4) -> 0
A31: Chrysli | B31: =Startlist2026!D59 -> BauhausPhilBahrain - Victorious | C31: =SUMIF(Ergebnisse_Roh!C$2:C$21,$B31,Punktematrix!$B$2:$B$21) -> 0 | D31: =SUMIF(Ergebnisse_Roh!D$2:D$21,$B31,Punktematrix!$B$2:$B$21) -> 0 | E31: =SUMIF(Ergebnisse_Roh!E$2:E$21,$B31,Punktematrix!$B$2:$B$21) -> 0 | F31: =SUMIF(Ergebnisse_Roh!F$2:F$21,$B31,Punktematrix!$B$2:$B$21) -> 0 | G31: =SUMIF(Ergebnisse_Roh!G$2:G$21,$B31,Punktematrix!$B$2:$B$21) -> 0 | H31: =SUMIF(Ergebnisse_Roh!H$2:H$21,$B31,Punktematrix!$B$2:$B$21) -> 0 | I31: =SUMIF(Ergebnisse_Roh!I$2:I$21,$B31,Punktematrix!$B$2:$B$21) -> 10 | J31: =SUMIF(Ergebnisse_Roh!J$2:J$21,$B31,Punktematrix!$B$2:$B$21) -> 0 | ... W31: =SUMIF(Ergebnisse_Roh!W$2:W$21,$B31,Punktematrix!$B$2:$B$21) -> 0 | X31: =SUMIF(Ergebnisse_Roh!X$2:X$16,$B31,Punktematrix!$C$2:$C$16) -> 0 | Y31: =SUMIF(Ergebnisse_Roh!Y$2:Y$11,$B31,Punktematrix!$D$2:$D$11) -> 0 | Z31: =SUMIF(Ergebnisse_Roh!Z$2:Z$11,$B31,Punktematrix!$E$2:$E$11) -> 0 | AA31: =SUMIF(Ergebnisse_Roh!AA$2:AA$4,$B31,Punktematrix!$F$2:$F$4) -> 0 | AB31: =SUMIF(Ergebnisse_Roh!AB$2:AB$4,$B31,Punktematrix!$G$2:$G$4) -> 0
A32: Chrysli | B32: =Startlist2026!D6 -> PolittNilsUAE Team Emirates - XRG | C32: =SUMIF(Ergebnisse_Roh!C$2:C$21,$B32,Punktematrix!$B$2:$B$21) -> 0 | D32: =SUMIF(Ergebnisse_Roh!D$2:D$21,$B32,Punktematrix!$B$2:$B$21) -> 0 | E32: =SUMIF(Ergebnisse_Roh!E$2:E$21,$B32,Punktematrix!$B$2:$B$21) -> 0 | F32: =SUMIF(Ergebnisse_Roh!F$2:F$21,$B32,Punktematrix!$B$2:$B$21) -> 0 | G32: =SUMIF(Ergebnisse_Roh!G$2:G$21,$B32,Punktematrix!$B$2:$B$21) -> 0 | H32: =SUMIF(Ergebnisse_Roh!H$2:H$21,$B32,Punktematrix!$B$2:$B$21) -> 0 | I32: =SUMIF(Ergebnisse_Roh!I$2:I$21,$B32,Punktematrix!$B$2:$B$21) -> 0 | J32: =SUMIF(Ergebnisse_Roh!J$2:J$21,$B32,Punktematrix!$B$2:$B$21) -> 0 | ... W32: =SUMIF(Ergebnisse_Roh!W$2:W$21,$B32,Punktematrix!$B$2:$B$21) -> 0 | X32: =SUMIF(Ergebnisse_Roh!X$2:X$16,$B32,Punktematrix!$C$2:$C$16) -> 0 | Y32: =SUMIF(Ergebnisse_Roh!Y$2:Y$11,$B32,Punktematrix!$D$2:$D$11) -> 0 | Z32: =SUMIF(Ergebnisse_Roh!Z$2:Z$11,$B32,Punktematrix!$E$2:$E$11) -> 0 | AA32: =SUMIF(Ergebnisse_Roh!AA$2:AA$4,$B32,Punktematrix!$F$2:$F$4) -> 0 | AB32: =SUMIF(Ergebnisse_Roh!AB$2:AB$4,$B32,Punktematrix!$G$2:$G$4) -> 0
A33: Chrysli | B33: =Startlist2026!D17 -> PiganzoliDavideTeam Visma | Lease a Bike | C33: =SUMIF(Ergebnisse_Roh!C$2:C$21,$B33,Punktematrix!$B$2:$B$21) -> 9 | D33: =SUMIF(Ergebnisse_Roh!D$2:D$21,$B33,Punktematrix!$B$2:$B$21) -> 0 | E33: =SUMIF(Ergebnisse_Roh!E$2:E$21,$B33,Punktematrix!$B$2:$B$21) -> 0 | F33: =SUMIF(Ergebnisse_Roh!F$2:F$21,$B33,Punktematrix!$B$2:$B$21) -> 0 | G33: =SUMIF(Ergebnisse_Roh!G$2:G$21,$B33,Punktematrix!$B$2:$B$21) -> 0 | H33: =SUMIF(Ergebnisse_Roh!H$2:H$21,$B33,Punktematrix!$B$2:$B$21) -> 0 | I33: =SUMIF(Ergebnisse_Roh!I$2:I$21,$B33,Punktematrix!$B$2:$B$21) -> 0 | J33: =SUMIF(Ergebnisse_Roh!J$2:J$21,$B33,Punktematrix!$B$2:$B$21) -> 0 | ... W33: =SUMIF(Ergebnisse_Roh!W$2:W$21,$B33,Punktematrix!$B$2:$B$21) -> 0 | X33: =SUMIF(Ergebnisse_Roh!X$2:X$16,$B33,Punktematrix!$C$2:$C$16) -> 10 | Y33: =SUMIF(Ergebnisse_Roh!Y$2:Y$11,$B33,Punktematrix!$D$2:$D$11) -> 0 | Z33: =SUMIF(Ergebnisse_Roh!Z$2:Z$11,$B33,Punktematrix!$E$2:$E$11) -> 0 | AA33: =SUMIF(Ergebnisse_Roh!AA$2:AA$4,$B33,Punktematrix!$F$2:$F$4) -> 0 | AB33: =SUMIF(Ergebnisse_Roh!AB$2:AB$4,$B33,Punktematrix!$G$2:$G$4) -> 0
